Workbook

Sheet Сводка
B1: Сводка по остаткам для ОЗОН
B2: Дата анализа: 18.08.2026 • валюта: ₽ (себестоимость по последнему приходу)
B4: Категория | C4: Позиций | D4: Себестоимость, ₽
B5: 1. Можно продать полностью | C5: =COUNTA('Можно продать'!C2:C57) -> 56 | D5: ='Можно продать'!G58 -> 28671013
B6: 2. Продать частично (всего) | C6: =COUNTA('Продать частично'!C2:C16) -> 15 | D6: ='Продать частично'!K17 -> 10271012
B7: из них: продадим за 6 мес | D7: ='Продать частично'!I17 -> 3534559.2
B8: из них: ОСТАНЕТСЯ (зависнет) | D8: ='Продать частично'!J17 -> 6736452.6
B9: 3. Нельзя продать | C9: =COUNTA('Нельзя продать'!C2:C33) -> 32 | D9: ='Нельзя продать'!F34 -> 10360777
B10: ИТОГО себестоимость всех остатков | C10: =C5+C6+C9 -> 103 | D10: =D5+D6+D9 -> 49302802
B12: Оценка ликвидности за 6 месяцев
B13: Реализуемо за 6 мес (полностью + продаваемая часть) | C13: =D13/D10 -> 0.65321992 | D13: =D5+D7 -> 32205572
B14: Зависает (остаток частичных + неликвид) | C14: =D14/D10 -> 0.34678008 | D14: =D8+D9 -> 17097230
B16: Примечания
B17: • Товар отнесён к «можно продать полностью», если запас уходит за 6 мес (продажи/мес × 6 ≥ остаток), иначе — «частично».
B18: • 2 позиции PETITFEE [1 pair] (Gold, Black Pearl & Gold) перенесены из «можно продать» в «нельзя продать»: пометка «да» стояла
B19: ошибочно, срок годности истёк (06.2025 и 11.2025). Включены в оптовый прайс со скидкой 50%.
B20: • 2 позиции MANYO (Bifida Biome Complex Ampoule и Bifida Complex Gel Cleanser) отнесены к «частично»: в колонке B не стояла
B21: пометка «не все кол-во», но по скорости продаж остаток не распродаётся за 6 мес.
B22: • ⚠️ COSRX Salicylic Cleanser — смешанная партия: часть (391 шт) с истёкшим сроком 01.2026, часть (200 шт) до 07.2027. Проверить физически.
B23: • HEIMISH All Clean Balm (мини) в «нельзя продать» — себестоимость не указана в исходнике, в сумму не вошла.
B24: • Красная заливка — просрочено; жёлтая — истекает в ближайшие 6 мес или смешанная партия.

Sheet Можно продать
A1: № | B1: Артикул WB | C1: Наименование | D1: Себестоимость за ед., ₽ | E1: Остаток, шт | F1: Продажи /мес | G1: Себестоимость остатка, ₽ | H1: Срок годности | I1: Статус срока
A2: 1 | B2: 204258828 | C2: COSRX - Salicylic Acid Daily Gentle Cleanser [150ml] / Пенка с салициловой кислотой для проблемной кожи | D2: 343.82 | E2: 410 | G2: =D2*E2 -> 140966.2 | H2: 01/26 (391шт) / 07/27 (200шт) | I2: смешанная партия — проверить
A3: 2 | B3: 608837066 | C3: DEOPROCE SHAMPOO - BLACK GARLIC INTENSME ENERGY [600ml] мягкая упаковка Шампунь с черным чесноком против выпадения волос | D3: 269.87 | E3: 66 | G3: =D3*E3 -> 17811.42
A4: 3 | B4: 214305722 | C4: DEOPROCE SHAMPOO+BALSAM - BLACK GARLIC[2000ml] | D4: 726.85 | E4: 443 | G4: =D4*E4 -> 321994.55
A5: 4 | B5: 199427475 | C5: DR. JART - Ctrl+A Teatreatment Toner [120ml] / Тонер тоник для лица увлажняющий с чайным деревом | D5: 637.89 | E5: 174 | G5: =D5*E5 -> 110992.86
A6: 5 | B6: 207796350 | C6: ELIZAVECCA - CER-100 Collagen Ceramide Coating Protein Treatment [100ml] / Коллагеновая маска для волос | D6: 242.23 | E6: 453 | G6: =D6*E6 -> 109730.19 | H6: 06.2028 | I6: ок
A7: 6 | B7: 190160008 | C7: ELIZAVECCA - Milky Piggy EGF elastic retinol [100ml] / Антивозрастной крем для лица с ретинолом и EGF | D7: 602.18 | E7: 235 | G7: =D7*E7 -> 141512.3 | H7: 01.2027 | I7: истекает <6 мес
A8: 7 | B8: 207796789 | C8: ENOUGH - Gold Snail Moisture Foundation [Tone 13] / Тональный крем с муцином улитки 13 тон | D8: 245.65 | E8: 95 | G8: =D8*E8 -> 23336.75
A9: 8 | B9: 207796898 | C9: ENOUGH - Gold Snail Moisture Foundation [Tone 21] / Тональный крем с муцином улитки 21 тон | D9: 270.81 | E9: 97 | G9: =D9*E9 -> 26268.57
A10: 9 | B10: 151132051 | C10: ENOUGH - Collagen 3in1 Whitening Moisture Foundation [Tone 13] / Тональный крем для лица с коллагеном 3в1 [13 тон] | D10: 238.13 | E10: 209 | G10: =D10*E10 -> 49769.17
A11: 10 | B11: 151132052 | C11: ENOUGH - Collagen 3in1 Whitening Moisture Foundation [Tone 21] / Тональный крем для лица с коллагеном 3в1 [21 тон] | D11: 223.35 | E11: 78 | G11: =D11*E11 -> 17421.3
A12: 11 | B12: 170198738 | C12: ENOUGH - Premium 8 Peptide Full Cover Perfect Foundation [Tone 13] / Тональный крем с пептидами 13 тон | D12: 335.9 | E12: 424 | G12: =D12*E12 -> 142421.6
A13: 12 | B13: 170198337 | C13: ENOUGH - Premium 8 Peptide Full Cover Perfect Foundation [Tone 21] / Тональный крем с пептидами 21 тон | D13: 304.77 | E13: 208 | G13: =D13*E13 -> 63392.16
A14: 13 | B14: 307073881 | C14: ETUDE - Baking Powder BB Deep Cleansing Foam [160ml] / Пенка с содой для глубокого очищения и снятия макияжа | D14: 292.89 | E14: 201 | G14: =D14*E14 -> 58870.89 | H14: 12.2027 | I14: ок
A15: 14 | B15: 154160085 | C15: ETUDE - Baking Powder Crunch Pore Scrub [24*7ml] / Очищающий скраб для лица с содой | D15: 389.99 | E15: 216 | G15: =D15*E15 -> 84237.84
A16: 15 | B16: 255574453 | C16: JIGOTT - Ассорти набор масок [27ml х 15] | D16: 334.05 | E16: 1350 | G16: =D16*E16 -> 450967.5
A17: 16 | B17: 198156472 | C17: MANYO - Galac Whitening Vita Serum [50ml] / Осветляющая сыворотка с Витамином C | D17: 646.83 | E17: 852 | F17: 150 | G17: =D17*E17 -> 551099.16
A18: 17 | B18: 198143251 | C18: MANYO - Bifida Biome Ampoule Lotion [300ml] / Укрепляющий лосьон с бифидобактериями | D18: 735.34 | E18: 744 | F18: 150 | G18: =D18*E18 -> 547092.96 | H18: 09.2027 | I18: ок
A19: 18 | B19: 198156698 | C19: MANYO - Pure Cleansing Oil [200ml] / Гидрофильное масло для глубокого очищения | D19: 853 | E19: 243 | F19: 60 | G19: =D19*E19 -> 207279 | H19: 08.2027 | I19: ок
A20: 19 | B20: 868700077 | C20: MANYO BIFIDA INFUSION SHOT AMPOULE 1DX [50ml] / Сыворотка с микроиглами и пробиотиками | D20: 996.75 | E20: 784 | F20: 350 | G20: =D20*E20 -> 781452
A21: 20 | B21: 179611231 | C21: PETITFEE - Collagen & CoQ10 Hydrogel Eye Patch [60ea] / Гидрогелевые патчи для глаз с коллагеном и коэнзимом Q10 | D21: 385.05 | E21: 1006 | G21: =D21*E21 -> 387360.3
A22: 21 | B22: 180988755 | C22: PETITFEE - Bera Glucan Deep Firming Eye Patch [60ea] / Тканевые патчи для век увлажняющие | D22: 486.69 | E22: 586 | G22: =D22*E22 -> 285200.34
A23: 22 | B23: 179611278 | C23: PETITFEE - Artichoke Soothing Hydrogel Eye Patch [60ea] / Смягчающие гидрогелевые патчи для глаз с экстрактом артишока | D23: 415.46 | E23: 300 | G23: =D23*E23 -> 124638
A24: 23 | B24: 180992464 | C24: PETITFEE - Aura Quartz Hydrogel Eye Patch [60ea] | D24: 591.29 | E24: 95 | G24: =D24*E24 -> 56172.55
A25: 24 | B25: 179611304 | C25: PETITFEE - Cacao Energizing Hydrogel Eye Patch [60ea] / Тонизирующие гидрогелевые патчи для глаз с экстрактом какао | D25: 415.46 | E25: 713 | G25: =D25*E25 -> 296222.98
A26: 25 | B26: 179611318 | C26: PETITFEE - Chamomile Lightening Hydrogel Eye Patch [60ea] / Успокаивающие гидрогелевые патчи для глаз с экстрактом ромашки | D26: 415.46 | E26: 288 | G26: =D26*E26 -> 119652.48
A27: 26 | B27: 180711041 | C27: PETITFEE - Gold & EGF Hydrogel Eye & Spot Patch [60ea]/ гидрогелевые патчи с золотом и EGF | D27: 385.05 | E27: 72 | G27: =D27*E27 -> 27723.6
A28: 27 | B28: 180987509 | C28: PETITFEE - Pink Vita Brightening Eye Patch [60ea] / Тканевые патчи для век увлажняющие | D28: 486.69 | E28: 267 | G28: =D28*E28 -> 129946.23
A29: 28 | B29: 151175880 | C29: PETITFEE - Black Pearl & Gold Hydrogel Eye Patch [60ea] / Гидрогелевые патчи для глаз с черным жемчугом и золотом | D29: 387.67 | E29: 909 | G29: =D29*E29 -> 352392.03
A30: 29 | B30: 151175877 | C30: PETITFEE - Agave Cooling Hydrogel Eye Patch [60ea] / Охлаждающие гидрогелевые патчи для глаз с экстрактом агавы | D30: 415.46 | E30: 933 | G30: =D30*E30 -> 387624.18
A31: 30 | B31: 179611207 | C31: PETITFEE - Gold & Snail Hydrogel Eye Patch [60ea] / Гидрогелевые патчи для глаз с золотом и улиткой | D31: 415.46 | E31: 877 | G31: =D31*E31 -> 364358.42
A32: 31 | B32: 180711104 | C32: PETITFEE - Gold Hydrogel Eye Patch [60ea] / гидрогелевые патчи для глаз с золотом | D32: 415.46 | E32: 694 | G32: =D32*E32 -> 288329.24
A33: 32 | B33: 226115324 | C33: PETITFEE - Agave Cooling Hydrogel Face Mask [5pcs] / Охлаждающая гидрогелевая маска для лица с экстрактом агавы | D33: 486.41 | E33: 951 | G33: =D33*E33 -> 462575.91 | H33: 11.2027 | I33: ок
A34: 33 | B34: 226114935 | C34: PETITFEE - Gold Hydrogel Mask Pack [5pcs] / Гидрогелевая маска для лица с золотом | D34: 507.16 | E34: 722 | G34: =D34*E34 -> 366169.52
A35: 34 | B35: 226115248 | C35: PETITFEE - Cacao Energizing Hydrogel Mask Pack [5pcs] / Тонизирующая гидрогелевая маска для лица с экстрактом какао | D35: 496.86 | E35: 609 | G35: =D35*E35 -> 302587.74
A36: 35 | B36: 226114831 | C36: PETITFEE - Artichoke Soothing Hydrogel Face Mask [5pcs] / Смягчающая гидрогелевая маска для лица с экстрактом артишока | D36: 498.54 | E36: 539 | G36: =D36*E36 -> 268713.06
A37: 36 | B37: 226115141 | C37: PETITFEE - Gold & Snail Hydrogel Mask Pack [5pcs] / Гидрогелевая маска для лица с золотом и экстрактом улитки | D37: 478.17 | E37: 453 | G37: =D37*E37 -> 216611.01
A38: 37 | B38: 226115478 | C38: PETITFEE - Black Pearl & Gold Hydrogel Mask Pack [5pcs] / Гидрогелевая маска для лица с черным жемчугом и золотом | D38: 478.05 | E38: 526 | G38: =D38*E38 -> 251454.3
A39: 38 | B39: 437154709 | C39: ROUND LAB 1025 DOKDO CLEANSER_150ml - Увлажняющая пенка для умывания лица | D39: 463.19 | E39: 7156 | G39: =D39*E39 -> 3314587.6
A40: 39 | B40: 437190353 | C40: ROUND LAB BIRCH JUICE MOISTURIZING CREAM_80ml -Увлажняющий крем с березовым соком | D40: 1092.96 | E40: 260 | G40: =D40*E40 -> 284169.6 | H40: 03.2028 | I40: ок
...

Sheet Продать частично
A1: № | B1: Артикул WB | C1: Наименование | D1: Себест. за ед., ₽ | E1: Остаток, шт | F1: Продажи /мес | G1: Продадим за 6 мес, шт | H1: Останется, шт | I1: Себест. продаваемого, ₽ | J1: Себест. остатка, ₽ | K1: Себест. всего, ₽ | L1: Срок годности | M1: Статус срока
A2: 1 | B2: 150925321 | C2: ENOUGH - Collagen Moisture Foundation [Tone 13] / Тональный крем для лица с коллагеном 13 тон | D2: 216.45 | E2: 1066 | F2: 150 | G2: =F2*6 -> 900 | H2: =E2-G2 -> 166 | I2: =D2*G2 -> 194805 | J2: =D2*H2 -> 35930.7 | K2: =D2*E2 -> 230735.7
A3: 2 | B3: 150925322 | C3: ENOUGH - Collagen Moisture Foundation [Tone 21] / Тональный крем для лица с коллагеном 21 тон | D3: 242.88 | E3: 2250 | F3: 150 | G3: =F3*6 -> 900 | H3: =E3-G3 -> 1350 | I3: =D3*G3 -> 218592 | J3: =D3*H3 -> 327888 | K3: =D3*E3 -> 546480
A4: 3 | B4: 151313163 | C4: ETUDE - Baking Powder Crunch Pore Scrub [200ml] / Очищающий скраб для лица с содой | D4: 361.03 | E4: 7902 | F4: 200 | G4: =F4*6 -> 1200 | H4: =E4-G4 -> 6702 | I4: =D4*G4 -> 433236 | J4: =D4*H4 -> 2419623.1 | K4: =D4*E4 -> 2852859.1 | L4: 02.2028 | M4: ок
A5: 4 | B5: 207466866 | C5: HEIMISH - Artless Glow Base SPF50+ PA+++(Renew) [40ml] / База под макияж SPF50+ PA+++ | D5: 770.48 | E5: 1025 | F5: 100 | G5: =F5*6 -> 600 | H5: =E5-G5 -> 425 | I5: =D5*G5 -> 462288 | J5: =D5*H5 -> 327454 | K5: =D5*E5 -> 789742
A6: 5 | B6: 207482718 | C6: JIGOTT - Snail Lifting Cream [70ml] / Крем для лица увлажняющий антивозрастной | D6: 202.27 | E6: 7618 | F6: 100 | G6: =F6*6 -> 600 | H6: =E6-G6 -> 7018 | I6: =D6*G6 -> 121362 | J6: =D6*H6 -> 1419530.9 | K6: =D6*E6 -> 1540892.9
A7: 6 | B7: 207483179 | C7: JIGOTT - Snail Reparing Cream [100ml] / Крем для лица увлажняющий антивозрастной с муцином улитки | D7: 185.86 | E7: 1233 | F7: 100 | G7: =F7*6 -> 600 | H7: =E7-G7 -> 633 | I7: =D7*G7 -> 111516 | J7: =D7*H7 -> 117649.38 | K7: =D7*E7 -> 229165.38
A8: 7 | B8: 207483780 | C8: JIGOTT - Birds Nest Firming Cream [70ml] / Антивозрастной крем с экстрактом ласточкиного гнезда | D8: 202.27 | E8: 1814 | F8: 50 | G8: =F8*6 -> 300 | H8: =E8-G8 -> 1514 | I8: =D8*G8 -> 60681 | J8: =D8*H8 -> 306236.78 | K8: =D8*E8 -> 366917.78 | L8: 06.2028 | M8: ок
A9: 8 | B9: 212760119 | C9: JIGOTT - Ultimate Real Collagen Toner [300ml] / тонер с коллагеном антивозрастной | D9: 265.36 | E9: 1296 | F9: 100 | G9: =F9*6 -> 600 | H9: =E9-G9 -> 696 | I9: =D9*G9 -> 159216 | J9: =D9*H9 -> 184690.56 | K9: =D9*E9 -> 343906.56
A10: 9 | B10: 212757456 | C10: JIGOTT - Daily Real Cica Toner [300ml] / Тонер для лица с центеллой азиатской | D10: 265.36 | E10: 1468 | F10: 100 | G10: =F10*6 -> 600 | H10: =E10-G10 -> 868 | I10: =D10*G10 -> 159216 | J10: =D10*H10 -> 230332.48 | K10: =D10*E10 -> 389548.48
A11: 10 | B11: 212883090 | C11: JIGOTT - Aura Secret Hyaluronec Acid Toner [300ml] / Тонер с гиалуроновой кислотой антивозрастной | D11: 265.36 | E11: 422 | F11: 50 | G11: =F11*6 -> 300 | H11: =E11-G11 -> 122 | I11: =D11*G11 -> 79608 | J11: =D11*H11 -> 32373.92 | K11: =D11*E11 -> 111981.92
A12: 11 | B12: 212759698 | C12: JIGOTT - Moisture Real Aloe Vera Toner [300ml] / Тонер для лица увлажняющий с экстрактом алоэ | D12: 265.36 | E12: 356 | F12: 50 | G12: =F12*6 -> 300 | H12: =E12-G12 -> 56 | I12: =D12*G12 -> 79608 | J12: =D12*H12 -> 14860.16 | K12: =D12*E12 -> 94468.16
A13: 12 | B13: 214977901 | C13: JMSOLUTION - MASK PACK BLACK [30ml*10ea] - ассорти набор 10шт в упаковке | D13: 463.2 | E13: 1039 | F13: 100 | G13: =F13*6 -> 600 | H13: =E13-G13 -> 439 | I13: =D13*G13 -> 277920 | J13: =D13*H13 -> 203344.8 | K13: =D13*E13 -> 481264.8
A14: 13 | B14: 214964091 | C14: JMSOLUTION - MASK PACK DISNEY [30ml*10ea] - ассорти набор из 10шт | D14: 463.2 | E14: 832 | F14: 100 | G14: =F14*6 -> 600 | H14: =E14-G14 -> 232 | I14: =D14*G14 -> 277920 | J14: =D14*H14 -> 107462.4 | K14: =D14*E14 -> 385382.4
A15: 14 | B15: 198147185 | C15: MANYO - Bifida Biome Complex Ampoule [50ml] / Антивозрастная сыворотка для лица | D15: 899.78 | E15: 1459 | F15: 150 | G15: =F15*6 -> 900 | H15: =E15-G15 -> 559 | I15: =D15*G15 -> 809802 | J15: =D15*H15 -> 502977.02 | K15: =D15*E15 -> 1312779
A16: 15 | B16: 868575374 | C16: MANYO BIFIDA COMPLEX AMPOULE GEL CLEANSER [400ml] / Гель для умывания с бифидобактериями | D16: 739.91 | E16: 804 | F16: 20 | G16: =F16*6 -> 120 | H16: =E16-G16 -> 684 | I16: =D16*G16 -> 88789.2 | J16: =D16*H16 -> 506098.44 | K16: =D16*E16 -> 594887.64
C17: ИТОГО «частично» | E17: =SUM(E2:E16) -> 30584 | G17: =SUM(G2:G16) -> 9120 | H17: =SUM(H2:H16) -> 21464 | I17: =SUM(I2:I16) -> 3534559.2 | J17: =SUM(J2:J16) -> 6736452.6 | K17: =SUM(K2:K16) -> 10271012

Sheet Нельзя продать
A1: № | B1: Артикул WB | C1: Наименование | D1: Себестоимость за ед., ₽ | E1: Остаток, шт | F1: Себестоимость остатка, ₽ | G1: Срок годности | H1: Статус срока
A2: 1 | B2: 608624295 | C2: DEOPROCE SHAMPOO - BLACK GARLIC INTENSME ENERGY [600ml] мягкая упаковка с колпачком,Шампунь с черным чесноком против выпадения волос | D2: 314.85 | E2: 16 | F2: =D2*E2 -> 5037.6
A3: 2 | B3: 608841921 | C3: DEOPROCE SHAMPOO - BLACK GARLIC INTENSME ENERGY [200ml]/ Шампунь с черным чесноком против выпадения волос | D3: 151.13 | E3: 370 | F3: =D3*E3 -> 55918.1
A4: 3 | B4: 208202076 | C4: EKEL - Ampule Сream Сollagen [70ml] / Крем для лица ампульный с коллагеном | D4: 142.13 | E4: 48 | F4: =D4*E4 -> 6822.24
A5: 4 | B5: 206058262 | C5: ELIZAVECCA - Hell-Pore Galactomyces Pure Ample / Сыворотка для лица с экстрактом галактомисиса | D5: 447.64 | E5: 50 | F5: =D5*E5 -> 22382 | G5: 05.2026 | H5: ПРОСРОЧЕН
A6: 5 | B6: 238415286 | C6: ENOUGH - Collagen Moisture Essential Cream [50ml] / Увлажняющий крем для лица с коллагеном | D6: 161.3 | E6: 8199 | F6: =D6*E6 -> 1322498.7
A7: 6 | B7: 238416010 | C7: ENOUGH - Collagen Whitening Moisture Cream 3in1 [50g] / Антивозрастной отбеливающий крем с коллагеном | D7: 183.88 | E7: 752 | F7: =D7*E7 -> 138277.76
A8: 7 | B8: 212889025 | C8: ENOUGH Collagen whitening cover tip concealer #01 [9g]/Консилер для лица (основная карточка) 4.5 рейтинг | D8: 183.24 | E8: 577 | F8: =D8*E8 -> 105729.48
A9: 8 | B9: 212889027 | C9: ENOUGH Collagen whitening cover tip concealer #02 [9g]/Консилер для лица (основная карточка) | D9: 183.24 | E9: 751 | F9: =D9*E9 -> 137613.24
A10: 9 | B10: 212889028 | C10: ENOUGH Collagen whitening cover tip concealer #03 [9g]/ Консилер для лица (основаная карточка) | D10: 183.24 | E10: 807 | F10: =D10*E10 -> 147874.68
A11: 10 | B11: 238413828 | C11: ENOUGH - Collagen Moisture BB Cream SPF47 PA+++ [50ml] / Увлажняющий BB крем с коллагеном | D11: 189.27 | E11: 717 | F11: =D11*E11 -> 135706.59 | G11: 10.2026 | H11: истекает <6 мес
A12: 11 | B12: 168956391 | C12: FARMSTAY - Collagen & Hyaluronic Acid All-In One Ampoule [250ml] / Сыворотка с коллагеном и гиалуроновой кислотой | D12: 347.76 | E12: 6608 | F12: =D12*E12 -> 2297998.1
A13: 12 | B13: 207472742 | C13: FARMSTAY - Black Garlic Nourishing Shampoo [530ml] / Шампунь-кондиционер 2в1 с экстрактом черного чеснока | D13: 396.72 | E13: 3354 | F13: =D13*E13 -> 1330598.9
A14: 13 | B14: 207469760 | C14: FARMSTAY - Gold Snail Premium Cream [50ml] / Омолаживающий крем с муцином улитки и коллоидным золотом | D14: 431.05 | E14: 1102 | F14: =D14*E14 -> 475017.1 | G14: 04.2028 | H14: ок
A15: 14 | B15: 169076150 | C15: FARMSTAY - Escargot Noblesse Intensive Cream [50g] / Крем с муцином королевской улитки | D15: 313.84 | E15: 962 | F15: =D15*E15 -> 301914.08
A16: 15 | B16: 419630142 | C16: FARMSTAY ESCARGOT NOBLESSE INTENSIVE AMPOULE/ сыворотка с улиткой | D16: 390.46 | E16: 1021 | F16: =D16*E16 -> 398659.66
A17: 16 | B17: 207476309 | C17: FARMSTAY - Argan Oil Complete Volume Up Shampoo & Conditioner [530ml] / Шампунь-кондиционер с аргановым маслом | D17: 400.76 | E17: 2524 | F17: =D17*E17 -> 1011518.2
A18: 17 | B18: 207475898 | C18: FARMSTAY - Collagen Water Full Shampoo & Conditioner [530ml] / Шампунь-кондиционер 2в1 с коллагеном | D18: 396.72 | E18: 3669 | F18: =D18*E18 -> 1455565.7
A19: 18 | B19: 212885914 | C19: FARMSTAY - Collagen Water Full Moist Rolling Eye Serum [25ml] / Сыворотка роллер для глаз | D19: 231.73 | E19: 470 | F19: =D19*E19 -> 108913.1
A20: 19 | B20: 207477077 | C20: FARMSTAY - Collagen Water Full Moist Cream [100g] / Увлажняющий крем с коллагеном | D20: 484.42 | E20: 277 | F20: =D20*E20 -> 134184.34
A21: 20 | B21: 207476777 | C21: FARMSTAY - Collagen Pure Cleansing Foam [180ml]/Пенка для умывания | D21: 161.47 | E21: 515 | F21: =D21*E21 -> 83157.05
A22: 21 | C22: HEIMISH - All Clean Balm / Очищающий гидрофильный бальзам щербет МИНИ ВЕРСИЯ | E22: 400 | F22: 0
A23: 22 | B23: 210575566 | C23: LEBELAGE - Dr. Peptide Derma Eye Cream [40ml] / Крем для глаз антивозрастной с пептидами | D23: 108.15 | E23: 410 | F23: =D23*E23 -> 44341.5
A24: 23 | B24: 868761530 | C24: LANEIGE LIP SLEEPING MASK-BERRY [3g] | D24: 130.86 | E24: 290 | F24: =D24*E24 -> 37949.4
A25: 24 | B25: 183030830 | C25: MASIL - 8 Seconds Salon Hair Mask 350ml Set [350ml+8ml*2] | D25: 669.05 | E25: 109 | F25: =D25*E25 -> 72926.45
A26: 25 | C26: PETITFEE - Black Pearl & Gold Hydrogel Eye Patch [1 pairs]/ Гидрогелевые патчи для глаз с черным жемчугом и золотом 1 пара | D26: 71.24 | E26: 320 | F26: =D26*E26 -> 22796.8 | G26: 11.2025 | H26: ПРОСРОЧЕН
A27: 26 | C27: PETITFEE - Gold Hydrogel Eye Patch [1 Pairs] / гидрогелевые патчи для глаз с золотом 1 пара | D27: 71.24 | E27: 428 | F27: =D27*E27 -> 30490.72 | G27: 06.2025 | H27: ПРОСРОЧЕН
A28: 27 | B28: 214311963 | C28: SKIN1004 - Madagascar Centella Ampoule [30ml] / Сыворотка для лица успокаивающая из экстракта центеллы. | D28: 367.89 | E28: 30 | F28: =D28*E28 -> 11036.7
A29: 28 | B29: 214312149 | C29: SKIN1004 - Madagascar Centella Hyalu-Cica Sleeping Pack [30ml] / Увлажняющая гиалуроновая ночная маска для сухой кожи | D29: 294.15 | E29: 22 | F29: =D29*E29 -> 6471.3
A30: 29 | B30: 248928046 | C30: SOME BY MI - AHA-BHA-PHA 30 Days Miracle Cleansing Bar [106g] / Мыло для проблемной кожи с aha bha кислотами | D30: 549.71 | E30: 527 | F30: =D30*E30 -> 289697.17 | G30: 08.2026 | H30: ПРОСРОЧЕН
A31: 30 | B31: 248929125 | C31: SOME BY MI - AHA-BHA-PHA 30 Days Miracle Cream [60g] / Крем для лица | D31: 1057.2 | E31: 55 | F31: =D31*E31 -> 58146 | G31: 12.2026 | H31: истекает <6 мес
A32: 31 | B32: 214312385 | C32: THE ORDINARY - Argireline Solution 10% [30ml] / Сыворотка для лица от прыщей и акне с ниацинамидом 10 % | D32: 722.04 | E32: 117 | F32: =D32*E32 -> 84478.68 | G32: 04.2026 | H32: ПРОСРОЧЕН
A33: 32 | B33: 247275092 | C33: THE ORDINARY - Glycolic Acid 7% Toning Solution [KOR] [240ml] / Тоник с гликолевой кислотой 7% | D33: 845.49 | E33: 32 | F33: =D33*E33 -> 27055.68 | G33: 10.2027 | H33: ок
C34: ИТОГО «нельзя продать» | E34: =SUM(E2:E33) -> 35529 | F34: =SUM(F2:F33) -> 10360777
