Workbook

Sheet Параметры
A1: ПАРАМЕТРЫ ПЛАНИРОВАНИЯ
A3: Категория | B3: Срок поставки, мес | C3: Буфер, мес | D3: Целевой запас, мес
A4: косметика | B4: 2 | C4: 1 | D4: 4
A5: НГ/Деды Морозы | B5: 2 | C5: 0 | D5: 0
A6: электроника | B6: 2 | C6: 1 | D6: 3
A8: Жёлтое — редактируешь. Целевой запас: сколько месяцев держать. НГ — сезонный, закупка только под сезон.

Sheet Мастер-план
A1: Категория | B1: Товар | C1: Арт Коротич | D1: Арт Крона | E1: Баркод | F1: Себес ₽ | G1: Остаток склад (пул) | H1: Ост WB Коротич | I1: Ост WB Крона | J1: Ост Ozon | K1: В пути | L1: Прод/мес Коротич WB | M1: Прод/мес Крона WB | N1: Прод/мес Коротич Ozon | O1: Прод/мес Крона Ozon | P1: Спрос ИТОГО/мес | Q1: Доступно всего | R1: Покрытие мес | S1: Целевой запас мес | T1: К заказу шт | U1: Статус
A2: НГ/Деды Морозы | B2: Дед Мороз (№1) красный с подарком за спиной | C2: 48905926 | D2: 535617707 | F2: 292 | G2: 2579 | L2: 0 | P2: =SUM(L2:O2) | Q2: =G2+H2+I2+J2+K2 | R2: =IF(P2=0,"",ROUND(Q2/P2,1)) | S2: =IFERROR(VLOOKUP(A2,Параметры!$A$4:$D$6,4,FALSE),0) | T2: =IF(P2=0,0,MAX(0,ROUND(P2*(2+1)-Q2,0))) | U2: =IF(P2=0,"нет продаж",IF(R2="","",IF(R2<3,"ГОРИТ",IF(R2>12,"затоварен","норм"))))
A3: НГ/Деды Морозы | B3: Дед Мороз (№10) серый | C3: 103431810 | D3: 535622291 | F3: 292 | G3: 1444 | L3: 0 | P3: =SUM(L3:O3) | Q3: =G3+H3+I3+J3+K3 | R3: =IF(P3=0,"",ROUND(Q3/P3,1)) | S3: =IFERROR(VLOOKUP(A3,Параметры!$A$4:$D$6,4,FALSE),0) | T3: =IF(P3=0,0,MAX(0,ROUND(P3*(2+1)-Q3,0))) | U3: =IF(P3=0,"нет продаж",IF(R3="","",IF(R3<3,"ГОРИТ",IF(R3>12,"затоварен","норм"))))
A4: НГ/Деды Морозы | B4: Дед Мороз (№11) в клетку | C4: 104590122 | D4: 535622293 | F4: 292 | G4: 5430 | L4: 0 | P4: =SUM(L4:O4) | Q4: =G4+H4+I4+J4+K4 | R4: =IF(P4=0,"",ROUND(Q4/P4,1)) | S4: =IFERROR(VLOOKUP(A4,Параметры!$A$4:$D$6,4,FALSE),0) | T4: =IF(P4=0,0,MAX(0,ROUND(P4*(2+1)-Q4,0))) | U4: =IF(P4=0,"нет продаж",IF(R4="","",IF(R4<3,"ГОРИТ",IF(R4>12,"затоварен","норм"))))
A5: НГ/Деды Морозы | B5: Дед Мороз (№11) 45см клетка | C5: 555134309 | F5: 452 | G5: 1920 | L5: 0 | P5: =SUM(L5:O5) | Q5: =G5+H5+I5+J5+K5 | R5: =IF(P5=0,"",ROUND(Q5/P5,1)) | S5: =IFERROR(VLOOKUP(A5,Параметры!$A$4:$D$6,4,FALSE),0) | T5: =IF(P5=0,0,MAX(0,ROUND(P5*(2+1)-Q5,0))) | U5: =IF(P5=0,"нет продаж",IF(R5="","",IF(R5<3,"ГОРИТ",IF(R5>12,"затоварен","норм"))))
A6: НГ/Деды Морозы | B6: Дед Мороз (№11) 50см клетка | C6: 555135716 | F6: 507 | G6: 30 | L6: 0 | P6: =SUM(L6:O6) | Q6: =G6+H6+I6+J6+K6 | R6: =IF(P6=0,"",ROUND(Q6/P6,1)) | S6: =IFERROR(VLOOKUP(A6,Параметры!$A$4:$D$6,4,FALSE),0) | T6: =IF(P6=0,0,MAX(0,ROUND(P6*(2+1)-Q6,0))) | U6: =IF(P6=0,"нет продаж",IF(R6="","",IF(R6<3,"ГОРИТ",IF(R6>12,"затоварен","норм"))))
A7: НГ/Деды Морозы | B7: Дед Мороз (№11) 85см клетка | C7: 555169767 | F7: 1157 | G7: 5 | L7: 0 | P7: =SUM(L7:O7) | Q7: =G7+H7+I7+J7+K7 | R7: =IF(P7=0,"",ROUND(Q7/P7,1)) | S7: =IFERROR(VLOOKUP(A7,Параметры!$A$4:$D$6,4,FALSE),0) | T7: =IF(P7=0,0,MAX(0,ROUND(P7*(2+1)-Q7,0))) | U7: =IF(P7=0,"нет продаж",IF(R7="","",IF(R7<3,"ГОРИТ",IF(R7>12,"затоварен","норм"))))
A8: НГ/Деды Морозы | B8: Дед Мороз (№12) белый лыжи белые боты | C8: 103441912 | D8: 535622295 | F8: 292 | G8: 3904 | L8: 0 | P8: =SUM(L8:O8) | Q8: =G8+H8+I8+J8+K8 | R8: =IF(P8=0,"",ROUND(Q8/P8,1)) | S8: =IFERROR(VLOOKUP(A8,Параметры!$A$4:$D$6,4,FALSE),0) | T8: =IF(P8=0,0,MAX(0,ROUND(P8*(2+1)-Q8,0))) | U8: =IF(P8=0,"нет продаж",IF(R8="","",IF(R8<3,"ГОРИТ",IF(R8>12,"затоварен","норм"))))
A9: НГ/Деды Морозы | B9: Дед Мороз (№13) белый лыжи черные боты | C9: 103442522 | D9: 535622301 | F9: 292 | G9: 996 | L9: 0 | P9: =SUM(L9:O9) | Q9: =G9+H9+I9+J9+K9 | R9: =IF(P9=0,"",ROUND(Q9/P9,1)) | S9: =IFERROR(VLOOKUP(A9,Параметры!$A$4:$D$6,4,FALSE),0) | T9: =IF(P9=0,0,MAX(0,ROUND(P9*(2+1)-Q9,0))) | U9: =IF(P9=0,"нет продаж",IF(R9="","",IF(R9<3,"ГОРИТ",IF(R9>12,"затоварен","норм"))))
A10: НГ/Деды Морозы | B10: Дед Мороз (№3) красный с мишкой | C10: 48906308 | D10: 535622280 | F10: 292 | G10: 3506 | L10: 0 | P10: =SUM(L10:O10) | Q10: =G10+H10+I10+J10+K10 | R10: =IF(P10=0,"",ROUND(Q10/P10,1)) | S10: =IFERROR(VLOOKUP(A10,Параметры!$A$4:$D$6,4,FALSE),0) | T10: =IF(P10=0,0,MAX(0,ROUND(P10*(2+1)-Q10,0))) | U10: =IF(P10=0,"нет продаж",IF(R10="","",IF(R10<3,"ГОРИТ",IF(R10>12,"затоварен","норм"))))
A11: НГ/Деды Морозы | B11: Дед Мороз (№3) 45см с мишкой | C11: 555204573 | F11: 452 | G11: 1421 | L11: 0 | P11: =SUM(L11:O11) | Q11: =G11+H11+I11+J11+K11 | R11: =IF(P11=0,"",ROUND(Q11/P11,1)) | S11: =IFERROR(VLOOKUP(A11,Параметры!$A$4:$D$6,4,FALSE),0) | T11: =IF(P11=0,0,MAX(0,ROUND(P11*(2+1)-Q11,0))) | U11: =IF(P11=0,"нет продаж",IF(R11="","",IF(R11<3,"ГОРИТ",IF(R11>12,"затоварен","норм"))))
A12: НГ/Деды Морозы | B12: Дед Мороз (№3) 50см с мишкой | C12: 555208894 | F12: 507 | G12: 60 | L12: 0 | P12: =SUM(L12:O12) | Q12: =G12+H12+I12+J12+K12 | R12: =IF(P12=0,"",ROUND(Q12/P12,1)) | S12: =IFERROR(VLOOKUP(A12,Параметры!$A$4:$D$6,4,FALSE),0) | T12: =IF(P12=0,0,MAX(0,ROUND(P12*(2+1)-Q12,0))) | U12: =IF(P12=0,"нет продаж",IF(R12="","",IF(R12<3,"ГОРИТ",IF(R12>12,"затоварен","норм"))))
A13: НГ/Деды Морозы | B13: Дед Мороз (№5) красный с подарком в руке | C13: 48906952 | D13: 535622285 | F13: 314 | G13: 4431 | L13: 0 | P13: =SUM(L13:O13) | Q13: =G13+H13+I13+J13+K13 | R13: =IF(P13=0,"",ROUND(Q13/P13,1)) | S13: =IFERROR(VLOOKUP(A13,Параметры!$A$4:$D$6,4,FALSE),0) | T13: =IF(P13=0,0,MAX(0,ROUND(P13*(2+1)-Q13,0))) | U13: =IF(P13=0,"нет продаж",IF(R13="","",IF(R13<3,"ГОРИТ",IF(R13>12,"затоварен","норм"))))
A14: НГ/Деды Морозы | B14: Дед Мороз (№5) 45см с подарком | C14: 555212357 | F14: 452 | G14: 1188 | L14: 0 | P14: =SUM(L14:O14) | Q14: =G14+H14+I14+J14+K14 | R14: =IF(P14=0,"",ROUND(Q14/P14,1)) | S14: =IFERROR(VLOOKUP(A14,Параметры!$A$4:$D$6,4,FALSE),0) | T14: =IF(P14=0,0,MAX(0,ROUND(P14*(2+1)-Q14,0))) | U14: =IF(P14=0,"нет продаж",IF(R14="","",IF(R14<3,"ГОРИТ",IF(R14>12,"затоварен","норм"))))
A15: НГ/Деды Морозы | B15: Дед Мороз (№5) 50см с подарком | C15: 555213580 | F15: 507 | G15: 200 | L15: 0 | P15: =SUM(L15:O15) | Q15: =G15+H15+I15+J15+K15 | R15: =IF(P15=0,"",ROUND(Q15/P15,1)) | S15: =IFERROR(VLOOKUP(A15,Параметры!$A$4:$D$6,4,FALSE),0) | T15: =IF(P15=0,0,MAX(0,ROUND(P15*(2+1)-Q15,0))) | U15: =IF(P15=0,"нет продаж",IF(R15="","",IF(R15<3,"ГОРИТ",IF(R15>12,"затоварен","норм"))))
A16: НГ/Деды Морозы | B16: Дед Мороз (№6) блестящий | C16: 48908708 | D16: 535622287 | F16: 292 | G16: 1519 | L16: 0 | P16: =SUM(L16:O16) | Q16: =G16+H16+I16+J16+K16 | R16: =IF(P16=0,"",ROUND(Q16/P16,1)) | S16: =IFERROR(VLOOKUP(A16,Параметры!$A$4:$D$6,4,FALSE),0) | T16: =IF(P16=0,0,MAX(0,ROUND(P16*(2+1)-Q16,0))) | U16: =IF(P16=0,"нет продаж",IF(R16="","",IF(R16<3,"ГОРИТ",IF(R16>12,"затоварен","норм"))))
A17: НГ/Деды Морозы | B17: Дед Мороз (№9) красный рябь | C17: 103431353 | D17: 535622289 | F17: 292 | G17: 1290 | L17: 0 | P17: =SUM(L17:O17) | Q17: =G17+H17+I17+J17+K17 | R17: =IF(P17=0,"",ROUND(Q17/P17,1)) | S17: =IFERROR(VLOOKUP(A17,Параметры!$A$4:$D$6,4,FALSE),0) | T17: =IF(P17=0,0,MAX(0,ROUND(P17*(2+1)-Q17,0))) | U17: =IF(P17=0,"нет продаж",IF(R17="","",IF(R17<3,"ГОРИТ",IF(R17>12,"затоварен","норм"))))
A18: НГ/Деды Морозы | B18: СГ-Белая с узорами | C18: 190314124 | F18: 304 | G18: 717 | L18: 0 | P18: =SUM(L18:O18) | Q18: =G18+H18+I18+J18+K18 | R18: =IF(P18=0,"",ROUND(Q18/P18,1)) | S18: =IFERROR(VLOOKUP(A18,Параметры!$A$4:$D$6,4,FALSE),0) | T18: =IF(P18=0,0,MAX(0,ROUND(P18*(2+1)-Q18,0))) | U18: =IF(P18=0,"нет продаж",IF(R18="","",IF(R18<3,"ГОРИТ",IF(R18>12,"затоварен","норм"))))
A19: НГ/Деды Морозы | B19: СГ-Красная | C19: 190314349 | F19: 304 | G19: 212 | L19: 0 | P19: =SUM(L19:O19) | Q19: =G19+H19+I19+J19+K19 | R19: =IF(P19=0,"",ROUND(Q19/P19,1)) | S19: =IFERROR(VLOOKUP(A19,Параметры!$A$4:$D$6,4,FALSE),0) | T19: =IF(P19=0,0,MAX(0,ROUND(P19*(2+1)-Q19,0))) | U19: =IF(P19=0,"нет продаж",IF(R19="","",IF(R19<3,"ГОРИТ",IF(R19>12,"затоварен","норм"))))
A20: косметика | B20: ENOUGH - Collagen Moisture Essential Cream [50ml] / Увлажняющий крем для лица с коллагеном | C20: 238415286 | E20: 20404410893540 | F20: 161 | G20: 6400 | L20: 840.8 | P20: =SUM(L20:O20) | Q20: =G20+H20+I20+J20+K20 | R20: =IF(P20=0,"",ROUND(Q20/P20,1)) | S20: =IFERROR(VLOOKUP(A20,Параметры!$A$4:$D$6,4,FALSE),0) | T20: =IF(P20=0,0,MAX(0,ROUND(P20*(2+1)-Q20,0))) | U20: =IF(P20=0,"нет продаж",IF(R20="","",IF(R20<3,"ГОРИТ",IF(R20>12,"затоварен","норм"))))
A21: косметика | B21: Celimax Dual Barrier Creamy Toner, тонер 150 мл | C21: 868516027 | E21: 20494769231520 | F21: 664 | G21: 15980 | L21: 462.7 | P21: =SUM(L21:O21) | Q21: =G21+H21+I21+J21+K21 | R21: =IF(P21=0,"",ROUND(Q21/P21,1)) | S21: =IFERROR(VLOOKUP(A21,Параметры!$A$4:$D$6,4,FALSE),0) | T21: =IF(P21=0,0,MAX(0,ROUND(P21*(2+1)-Q21,0))) | U21: =IF(P21=0,"нет продаж",IF(R21="","",IF(R21<3,"ГОРИТ",IF(R21>12,"затоварен","норм"))))
A22: косметика | B22: ROUND LAB 1025 DOKDO CLEANSER_150ml - Увлажняющая пенка для умывания лица | C22: 437154709 | E22: 20443216637880 | F22: 463 | G22: 5499 | L22: 460.6 | P22: =SUM(L22:O22) | Q22: =G22+H22+I22+J22+K22 | R22: =IF(P22=0,"",ROUND(Q22/P22,1)) | S22: =IFERROR(VLOOKUP(A22,Параметры!$A$4:$D$6,4,FALSE),0) | T22: =IF(P22=0,0,MAX(0,ROUND(P22*(2+1)-Q22,0))) | U22: =IF(P22=0,"нет продаж",IF(R22="","",IF(R22<3,"ГОРИТ",IF(R22>12,"затоварен","норм"))))
A23: косметика | B23: JIGOTT - Snail Lifting Cream [70ml] / Крем для лица увлажняющий антивозрастной | C23: 207482718 | E23: 20394552183240 | F23: 202 | G23: 7139 | L23: 299.8 | P23: =SUM(L23:O23) | Q23: =G23+H23+I23+J23+K23 | R23: =IF(P23=0,"",ROUND(Q23/P23,1)) | S23: =IFERROR(VLOOKUP(A23,Параметры!$A$4:$D$6,4,FALSE),0) | T23: =IF(P23=0,0,MAX(0,ROUND(P23*(2+1)-Q23,0))) | U23: =IF(P23=0,"нет продаж",IF(R23="","",IF(R23<3,"ГОРИТ",IF(R23>12,"затоварен","норм"))))
A24: косметика | B24: FARMSTAY - Collagen & Hyaluronic Acid All-In One Ampoule [250ml] / Сыворотка с коллагеном и гиалуроновой кислотой | C24: 168956391 | E24: 20381577225110 | F24: 348 | G24: 6067 | L24: 248.8 | P24: =SUM(L24:O24) | Q24: =G24+H24+I24+J24+K24 | R24: =IF(P24=0,"",ROUND(Q24/P24,1)) | S24: =IFERROR(VLOOKUP(A24,Параметры!$A$4:$D$6,4,FALSE),0) | T24: =IF(P24=0,0,MAX(0,ROUND(P24*(2+1)-Q24,0))) | U24: =IF(P24=0,"нет продаж",IF(R24="","",IF(R24<3,"ГОРИТ",IF(R24>12,"затоварен","норм"))))
A25: косметика | B25: PETITFEE - Gold & Snail Hydrogel Eye Patch [60ea] / Гидрогелевые патчи для глаз с золотом и улиткой | C25: 179611207 | E25: 20387078660090 | F25: 415 | G25: 608 | L25: 239 | P25: =SUM(L25:O25) | Q25: =G25+H25+I25+J25+K25 | R25: =IF(P25=0,"",ROUND(Q25/P25,1)) | S25: =IFERROR(VLOOKUP(A25,Параметры!$A$4:$D$6,4,FALSE),0) | T25: =IF(P25=0,0,MAX(0,ROUND(P25*(2+1)-Q25,0))) | U25: =IF(P25=0,"нет продаж",IF(R25="","",IF(R25<3,"ГОРИТ",IF(R25>12,"затоварен","норм"))))
A26: косметика | B26: FARMSTAY - Escargot Noblesse Intensive Cream [50g] / Крем с муцином королевской улитки | C26: 169076150 | E26: 20381610076800 | F26: 314 | G26: 835 | L26: 232.5 | P26: =SUM(L26:O26) | Q26: =G26+H26+I26+J26+K26 | R26: =IF(P26=0,"",ROUND(Q26/P26,1)) | S26: =IFERROR(VLOOKUP(A26,Параметры!$A$4:$D$6,4,FALSE),0) | T26: =IF(P26=0,0,MAX(0,ROUND(P26*(2+1)-Q26,0))) | U26: =IF(P26=0,"нет продаж",IF(R26="","",IF(R26<3,"ГОРИТ",IF(R26>12,"затоварен","норм"))))
A27: косметика | B27: JIGOTT - Snail Reparing Cream [100ml] / Крем для лица увлажняющий антивозрастной с муцином улитки | C27: 207483179 | E27: 20394552220930 | F27: 186 | G27: 777 | L27: 215.1 | P27: =SUM(L27:O27) | Q27: =G27+H27+I27+J27+K27 | R27: =IF(P27=0,"",ROUND(Q27/P27,1)) | S27: =IFERROR(VLOOKUP(A27,Параметры!$A$4:$D$6,4,FALSE),0) | T27: =IF(P27=0,0,MAX(0,ROUND(P27*(2+1)-Q27,0))) | U27: =IF(P27=0,"нет продаж",IF(R27="","",IF(R27<3,"ГОРИТ",IF(R27>12,"затоварен","норм"))))
A28: косметика | B28: PETITFEE - Black Pearl & Gold Hydrogel Eye Patch [60ea] / Гидрогелевые патчи для глаз с черным жемчугом и золотом | C28: 151175880 | E28: 20375937346520 | F28: 388 | G28: 549 | L28: 173.8 | P28: =SUM(L28:O28) | Q28: =G28+H28+I28+J28+K28 | R28: =IF(P28=0,"",ROUND(Q28/P28,1)) | S28: =IFERROR(VLOOKUP(A28,Параметры!$A$4:$D$6,4,FALSE),0) | T28: =IF(P28=0,0,MAX(0,ROUND(P28*(2+1)-Q28,0))) | U28: =IF(P28=0,"нет продаж",IF(R28="","",IF(R28<3,"ГОРИТ",IF(R28>12,"затоварен","норм"))))
A29: косметика | B29: FARMSTAY - Black Garlic Nourishing Shampoo [530ml] / Шампунь-кондиционер 2в1 с экстрактом черного чеснока | C29: 207472742 | E29: 20394551238880 | F29: 397 | G29: 3200 | L29: 152.1 | P29: =SUM(L29:O29) | Q29: =G29+H29+I29+J29+K29 | R29: =IF(P29=0,"",ROUND(Q29/P29,1)) | S29: =IFERROR(VLOOKUP(A29,Параметры!$A$4:$D$6,4,FALSE),0) | T29: =IF(P29=0,0,MAX(0,ROUND(P29*(2+1)-Q29,0))) | U29: =IF(P29=0,"нет продаж",IF(R29="","",IF(R29<3,"ГОРИТ",IF(R29>12,"затоварен","норм"))))
A30: косметика | B30: PETITFEE - Agave Cooling Hydrogel Eye Patch [60ea] / Охлаждающие гидрогелевые патчи для глаз с экстрактом агавы | C30: 151175877 | E30: 20375937296890 | F30: 415 | G30: 501 | L30: 148.8 | P30: =SUM(L30:O30) | Q30: =G30+H30+I30+J30+K30 | R30: =IF(P30=0,"",ROUND(Q30/P30,1)) | S30: =IFERROR(VLOOKUP(A30,Параметры!$A$4:$D$6,4,FALSE),0) | T30: =IF(P30=0,0,MAX(0,ROUND(P30*(2+1)-Q30,0))) | U30: =IF(P30=0,"нет продаж",IF(R30="","",IF(R30<3,"ГОРИТ",IF(R30>12,"затоварен","норм"))))
A31: косметика | B31: FARMSTAY - Argan Oil Complete Volume Up Shampoo & Conditioner [530ml] / Шампунь-кондиционер с аргановым маслом | C31: 207476309 | E31: 20394551530900 | F31: 401 | G31: 2298 | L31: 142.3 | P31: =SUM(L31:O31) | Q31: =G31+H31+I31+J31+K31 | R31: =IF(P31=0,"",ROUND(Q31/P31,1)) | S31: =IFERROR(VLOOKUP(A31,Параметры!$A$4:$D$6,4,FALSE),0) | T31: =IF(P31=0,0,MAX(0,ROUND(P31*(2+1)-Q31,0))) | U31: =IF(P31=0,"нет продаж",IF(R31="","",IF(R31<3,"ГОРИТ",IF(R31>12,"затоварен","норм"))))
... A129: косметика | B129: MANYO BIFIDA INFUSION SHOT AMPOULE 1DX [50ml] / Сыворотка с микроиглами и пробиотиками | C129: 868700077 | E129: 20494786120300 | F129: 997 | G129: 603 | L129: 2.2 | P129: =SUM(L129:O129) | Q129: =G129+H129+I129+J129+K129 | R129: =IF(P129=0,"",ROUND(Q129/P129,1)) | S129: =IFERROR(VLOOKUP(A129,Параметры!$A$4:$D$6,4,FALSE),0) | T129: =IF(P129=0,0,MAX(0,ROUND(P129*(2+1)-Q129,0))) | U129: =IF(P129=0,"нет продаж",IF(R129="","",IF(R129<3,"ГОРИТ",IF(R129>12,"затоварен","норм"))))
A130: косметика | B130: ROUND LAB VITA NIACINAMIDE DARK SPOT CREAM 50ml - Крем для лица с ниацинамидом от чёрных точек | C130: 1123574113 | F130: 1025 | G130: 0 | L130: 2.2 | P130: =SUM(L130:O130) | Q130: =G130+H130+I130+J130+K130 | R130: =IF(P130=0,"",ROUND(Q130/P130,1)) | S130: =IFERROR(VLOOKUP(A130,Параметры!$A$4:$D$6,4,FALSE),0) | T130: =IF(P130=0,0,MAX(0,ROUND(P130*(2+1)-Q130,0))) | U130: =IF(P130=0,"нет продаж",IF(R130="","",IF(R130<3,"ГОРИТ",IF(R130>12,"затоварен","норм"))))
A131: косметика | B131: SKIN1004 - Madagascar Centella Ampoule [30ml] / Сыворотка для лица успокаивающая из экстракта центеллы. | C131: 214311963 | E131: 20395981417940 | F131: 368 | G131: 30 | L131: 2.2 | P131: =SUM(L131:O131) | Q131: =G131+H131+I131+J131+K131 | R131: =IF(P131=0,"",ROUND(Q131/P131,1)) | S131: =IFERROR(VLOOKUP(A131,Параметры!$A$4:$D$6,4,FALSE),0) | T131: =IF(P131=0,0,MAX(0,ROUND(P131*(2+1)-Q131,0))) | U131: =IF(P131=0,"нет продаж",IF(R131="","",IF(R131<3,"ГОРИТ",IF(R131>12,"затоварен","норм"))))
A132: косметика | B132: CELIMAX THE REAL NONI STARTER KIT (NEW) [30ml+10ml+10ml]/Восстанавливающий набор миниатюр с нони (Тоник, сыворотка, крем ) | C132: 551616449 | E132: 20464112148180 | F132: 634 | G132: 0 | L132: 2.2 | P132: =SUM(L132:O132) | Q132: =G132+H132+I132+J132+K132 | R132: =IF(P132=0,"",ROUND(Q132/P132,1)) | S132: =IFERROR(VLOOKUP(A132,Параметры!$A$4:$D$6,4,FALSE),0) | T132: =IF(P132=0,0,MAX(0,ROUND(P132*(2+1)-Q132,0))) | U132: =IF(P132=0,"нет продаж",IF(R132="","",IF(R132<3,"ГОРИТ",IF(R132>12,"затоварен","норм"))))
A133: косметика | B133: CELIMAX PORE+DARK SPOT BRIGHTENING PAD [100ml / 40pads]/Тонер-пэды для выравнивания тона и рельефа кожи | C133: 551540924 | E133: 20464072454990 | F133: 556 | G133: 1375 | L133: 2.2 | P133: =SUM(L133:O133) | Q133: =G133+H133+I133+J133+K133 | R133: =IF(P133=0,"",ROUND(Q133/P133,1)) | S133: =IFERROR(VLOOKUP(A133,Параметры!$A$4:$D$6,4,FALSE),0) | T133: =IF(P133=0,0,MAX(0,ROUND(P133*(2+1)-Q133,0))) | U133: =IF(P133=0,"нет продаж",IF(R133="","",IF(R133<3,"ГОРИТ",IF(R133>12,"затоварен","норм"))))
A134: косметика | B134: CELIMAX PORE+DARK SPOT BRIGHTENING SERUM_30ml [30ml]/Сыворотка для выравнивания тона и рельефа кожи лица | C134: 551482493 | E134: 20464057080190 | F134: 688 | G134: 77 | L134: 2.2 | P134: =SUM(L134:O134) | Q134: =G134+H134+I134+J134+K134 | R134: =IF(P134=0,"",ROUND(Q134/P134,1)) | S134: =IFERROR(VLOOKUP(A134,Параметры!$A$4:$D$6,4,FALSE),0) | T134: =IF(P134=0,0,MAX(0,ROUND(P134*(2+1)-Q134,0))) | U134: =IF(P134=0,"нет продаж",IF(R134="","",IF(R134<3,"ГОРИТ",IF(R134>12,"затоварен","норм"))))
A135: косметика | B135: ELIZAVECCA - Hell-Pore Galactomyces Pure Ample / Сыворотка для лица с экстрактом галактомисиса | C135: 206058262 | E135: 20394264354840 | F135: 448 | G135: 50 | L135: 1.1 | P135: =SUM(L135:O135) | Q135: =G135+H135+I135+J135+K135 | R135: =IF(P135=0,"",ROUND(Q135/P135,1)) | S135: =IFERROR(VLOOKUP(A135,Параметры!$A$4:$D$6,4,FALSE),0) | T135: =IF(P135=0,0,MAX(0,ROUND(P135*(2+1)-Q135,0))) | U135: =IF(P135=0,"нет продаж",IF(R135="","",IF(R135<3,"ГОРИТ",IF(R135>12,"затоварен","норм"))))
A136: косметика | B136: ENOUGH - Collagen 3in1 Sun Cream SPF50 PA+++ [50ml] / отбеливающий увлажняющий солнцезащитный крем 3в1 | C136: 238358954 | E136: 20404396861450 | F136: 203 | G136: 0 | L136: 1.1 | P136: =SUM(L136:O136) | Q136: =G136+H136+I136+J136+K136 | R136: =IF(P136=0,"",ROUND(Q136/P136,1)) | S136: =IFERROR(VLOOKUP(A136,Параметры!$A$4:$D$6,4,FALSE),0) | T136: =IF(P136=0,0,MAX(0,ROUND(P136*(2+1)-Q136,0))) | U136: =IF(P136=0,"нет продаж",IF(R136="","",IF(R136<3,"ГОРИТ",IF(R136>12,"затоварен","норм"))))
A137: косметика | B137: ETUDE - Baking Powder Pore Cleansing Foam [160ml] / Пенка для умывания с содой | C137: 169198316 | F137: 260 | G137: 0 | L137: 1.1 | P137: =SUM(L137:O137) | Q137: =G137+H137+I137+J137+K137 | R137: =IF(P137=0,"",ROUND(Q137/P137,1)) | S137: =IFERROR(VLOOKUP(A137,Параметры!$A$4:$D$6,4,FALSE),0) | T137: =IF(P137=0,0,MAX(0,ROUND(P137*(2+1)-Q137,0))) | U137: =IF(P137=0,"нет продаж",IF(R137="","",IF(R137<3,"ГОРИТ",IF(R137>12,"затоварен","норм"))))
...

Sheet Инструкция
A1: МАСТЕР-ФАЙЛ ПЛАНИРОВАНИЯ — как пользоваться
A3: 1 строка = 1 физический товар (по баркоду/себестоимости). Склад общий на оба магазина.
A4: Жёлтые колонки — заполняешь выгрузками; зелёные считаются сами.
A6: Что заполнить:
A7: - Ост WB Коротич/Крона, Ост Ozon, В пути — из остатков каналов.
A8: - Прод/мес Коротич WB — уже заполнено (Ракета 31.08-27.09). Крона WB, Коротич Ozon, Крона Ozon — из выгрузок.
A10: Считается само:
A11: - Спрос ИТОГО/мес = сумма продаж по 4 витринам.
A12: - Доступно = склад+FBO+Ozon+пути.
A13: - Покрытие мес = доступно / спрос.
A14: - К заказу = спрос×(срок поставки+буфер) − доступно (параметры по категории).
A15: - Статус: ГОРИТ (<3 мес), норм, затоварен (>12 мес), нет продаж.
... A18: Электроника: в основном распродажа неликвида, точечно Рация/Скалер.
