Workbook

Sheet 상품리스트
A1: 신제품 | H1: 0.5
A2: 자재 | B2: 기존자재번호 | C2: Barcode | D2: Product list | E2: Volume | F2: - | G2: Retail Price | H2: Supply Price | I2: Supply Price | J2: TA | K2: BOX | L2: PAL | M2: 크기/치수 | N2: 내역 | O2: 사용기한 | P2: HS Code | Q2: BOX | R2: 박스무게(kg) | S2: g/w (g) | T2: 비고 | U2: 부가세제외가(SAP기준) | V2: 라인명 | W2: CPNP | X2: MoCRA | Y2: Quantity | Z2: Amount
A3: 650012009 | C3: 8809820713396 | D3: ET.Drawi.Eyes.Browcara_07CG_5g(26AD) | E3: 5 | F3: G | G3: 9000 | H3: =ROUNDUP(G3*$H$1,-1) -> 4500 | I3: =H3/1340 -> 3.358209 | J3: 6 | K3: 180 | L3: 11520 | M3: 27*19*121MM(15*15*119) | N3: 신제품 생산/구매 확정 | O3: 36 | P3: 3304209000 | Q3: 422*310*135mm | R3: 6.1 | S3: 30 | U3: 8182 | V3: 드로잉아이즈컬러링브로우카라26AD | W3: =IFERROR(VLOOKUP(A3,'[1]CPNP,SCPN 허가번호 리스트(필터 재정비)'!$C:$J,8,0),0) -> 0 | X3: =IFERROR(VLOOKUP(A3,[2]수록현황_260107!$D:$I,6,0),0) -> 0
A4: 650012013 | C4: 8809820714706 | D4: ET.Drawi.Eyes.Browcara_08DR_5g(26AD) | E4: 5 | F4: G | G4: 9000 | H4: =ROUNDUP(G4*$H$1,-1) -> 4500 | I4: =H4/1340 -> 3.358209 | J4: 6 | K4: 180 | L4: 11520 | M4: 27*19*121MM(15*15*119) | N4: 신제품 생산/구매 확정 | O4: 36 | P4: 3304209000 | Q4: 422*310*135mm | R4: 6.1 | S4: 30 | U4: 8182 | V4: 드로잉아이즈컬러링브로우카라26AD | W4: =IFERROR(VLOOKUP(A4,'[1]CPNP,SCPN 허가번호 리스트(필터 재정비)'!$C:$J,8,0),0) -> 0 | X4: =IFERROR(VLOOKUP(A4,[2]수록현황_260107!$D:$I,6,0),0) -> 0
A5: 650004291 | C5: 8809820714072 | D5: ET.Curl Fix Mascara 05 Long lash 8g | E5: 8 | F5: G | G5: 16000 | H5: =ROUNDUP(G5*$H$1,-1) -> 8000 | I5: =H5/1340 -> 5.9701493 | J5: 6 | K5: 126 | L5: 8064 | M5: 30*21*119MM | N5: 신제품 생산/구매 확정 | O5: 36 | P5: 3304209000 | Q5: 394*324*150mm | R5: 4.228 | S5: 28 | U5: 14545 | V5: 컬픽스마스카라 | W5: =IFERROR(VLOOKUP(A5,'[1]CPNP,SCPN 허가번호 리스트(필터 재정비)'!$C:$J,8,0),0) -> 0 | X5: =IFERROR(VLOOKUP(A5,[2]수록현황_260107!$D:$I,6,0),0) -> 0
A6: 650004287 | C6: 8809820715581 | D6: ET.Bare Edge Slim Brow_06GrayTaupe_0.1g | E6: 0.1 | F6: G | G6: 8000 | H6: =ROUNDUP(G6*$H$1,-1) -> 4000 | I6: =H6/1340 -> 2.9850746 | J6: 10 | K6: 360 | L6: 23040 | M6: 18*11*148MM | N6: 신제품 생산/구매 확정 | O6: 36 | P6: 3304209000 | Q6: 400*272*167mm | R6: 4.3 | S6: 10 | U6: 7273 | V6: 베어엣지슬림브로우 | W6: =IFERROR(VLOOKUP(A6,'[1]CPNP,SCPN 허가번호 리스트(필터 재정비)'!$C:$J,8,0),0) -> 0 | X6: =IFERROR(VLOOKUP(A6,[2]수록현황_260107!$D:$I,6,0),0) -> 0
A7: 650004288 | C7: 8809820715598 | D7: ET.Bare Edge Slim Brow_07RosyTaupe_0.1g | E7: 0.1 | F7: G | G7: 8000 | H7: =ROUNDUP(G7*$H$1,-1) -> 4000 | I7: =H7/1340 -> 2.9850746 | J7: 10 | K7: 360 | L7: 23040 | M7: 18*11*148MM | N7: 신제품 생산/구매 확정 | O7: 36 | P7: 3304209000 | Q7: 400*272*167mm | R7: 4.3 | S7: 10 | U7: 7273 | V7: 베어엣지슬림브로우 | W7: =IFERROR(VLOOKUP(A7,'[1]CPNP,SCPN 허가번호 리스트(필터 재정비)'!$C:$J,8,0),0) -> 0 | X7: =IFERROR(VLOOKUP(A7,[2]수록현황_260107!$D:$I,6,0),0) -> 0
A8: 650003685 | C8: 8809820700228 | D8: ET.(MBS)Bare Edge Makeup Multi Sealer | E8: 8 | F8: G | G8: 15000 | H8: =ROUNDUP(G8*$H$1,-1) -> 7500 | I8: =H8/1340 -> 5.5970149 | J8: 6 | K8: 216 | L8: 12096 | M8: 22*22*78MM | N8: =VLOOKUP(A8,[3]Sheet2!$A:$J,10,0) -> 러닝 본품 B (상위 50~80%) | O8: 24 | P8: 3304992000 | Q8: 394*324*195mm | R8: 17.98 | S8: 48 | U8: 13636 | V8: 베어엣지 | W8: =IFERROR(VLOOKUP(A8,'[1]CPNP,SCPN 허가번호 리스트(필터 재정비)'!$C:$J,8,0),0) -> 0 | X8: =IFERROR(VLOOKUP(A8,[2]수록현황_260107!$D:$I,6,0),0) -> 허가 유효
A9: 650003668 | B9: 650003248 | C9: 8809820695630 | D9: ET.(MBS)Bare Edge Slim brow 01(23) | E9: 0.1 | F9: G | G9: 8000 | H9: =ROUNDUP(G9*$H$1,-1) -> 4000 | I9: =H9/1340 -> 2.9850746 | J9: 10 | K9: 360 | L9: 23040 | M9: 18*11*148MM | N9: =VLOOKUP(A9,[3]Sheet2!$A:$J,10,0) -> 러닝 본품 C (상위 80~95%) | O9: 36 | P9: 3304209000 | Q9: 400*272*167mm | R9: 4.3 | S9: 10 | U9: 7273 | V9: 베어엣지슬림브로우 | W9: =IFERROR(VLOOKUP(A9,'[1]CPNP,SCPN 허가번호 리스트(필터 재정비)'!$C:$J,8,0),0) -> 0 | X9: =IFERROR(VLOOKUP(A9,[2]수록현황_260107!$D:$I,6,0),0) -> 0
A10: 111080745 | B10: 111080630 | C10: 8809820699232 | D10: ET.0.2TherapyAirMask_Aloe_20ml('23) | E10: 20 | F10: ML | G10: 1500 | H10: =ROUNDUP(G10*$H$1,-1) -> 750 | I10: =H10/1340 -> 0.55970149 | J10: 50 | K10: 300 | L10: 18000 | M10: 109*4*170MM | N10: =VLOOKUP(A10,[3]Sheet2!$A:$J,10,0) -> 생산 중지예정 | O10: 36 | P10: 3307904000 | Q10: 430*317*205*mm | R10: 9.7 | S10: 30 | U10: 1364 | V10: 0.2테라피 | W10: =IFERROR(VLOOKUP(A10,'[1]CPNP,SCPN 허가번호 리스트(필터 재정비)'!$C:$J,8,0),0) -> 0 | X10: =IFERROR(VLOOKUP(A10,[2]수록현황_260107!$D:$I,6,0),0) -> 허가 유효
A11: 111080746 | B11: 111080631 | C11: 8809820699249 | D11: ET.0.2TherapyAirMask_TeaTree_20ml('23) | E11: 20 | F11: ML | G11: 1500 | H11: =ROUNDUP(G11*$H$1,-1) -> 750 | I11: =H11/1340 -> 0.55970149 | J11: 50 | K11: 300 | L11: 18000 | M11: 109*4*170MM | N11: =VLOOKUP(A11,[3]Sheet2!$A:$J,10,0) -> 생산 중지예정 | O11: 36 | P11: 3307909000 | Q11: 430*317*205*mm | R11: 9.7 | S11: 30 | U11: 1364 | V11: 0.2테라피 | W11: =IFERROR(VLOOKUP(A11,'[1]CPNP,SCPN 허가번호 리스트(필터 재정비)'!$C:$J,8,0),0) -> 단종 및 내용물 AD 예정 | X11: =IFERROR(VLOOKUP(A11,[2]수록현황_260107!$D:$I,6,0),0) -> 허가 유효
A12: 111080747 | B12: 111080632 | C12: 8809820699256 | D12: ET.0.2TherapyAirMask_GreenTea_20ml('23) | E12: 20 | F12: ML | G12: 1500 | H12: =ROUNDUP(G12*$H$1,-1) -> 750 | I12: =H12/1340 -> 0.55970149 | J12: 50 | K12: 300 | L12: 18000 | M12: 109*4*170MM | N12: =VLOOKUP(A12,[3]Sheet2!$A:$J,10,0) -> 생산 중지예정 | O12: 36 | P12: 3307909000 | Q12: 430*317*205*mm | R12: 9.7 | S12: 30 | U12: 1364 | V12: 0.2테라피 | W12: =IFERROR(VLOOKUP(A12,'[1]CPNP,SCPN 허가번호 리스트(필터 재정비)'!$C:$J,8,0),0) -> 0 | X12: =IFERROR(VLOOKUP(A12,[2]수록현황_260107!$D:$I,6,0),0) -> 허가 유효
A13: 111080748 | B13: 111080633 | C13: 8809820699263 | D13: ET.0.2TherapyAirMask_Pearl_20ml('23) | E13: 20 | F13: ML | G13: 1500 | H13: =ROUNDUP(G13*$H$1,-1) -> 750 | I13: =H13/1340 -> 0.55970149 | J13: 50 | K13: 300 | L13: 18000 | M13: 109*4*170MM | N13: =VLOOKUP(A13,[3]Sheet2!$A:$J,10,0) -> 생산 중지예정 | O13: 36 | P13: 3307909000 | Q13: 430*317*205*mm | R13: 9.7 | S13: 30 | U13: 1364 | V13: 0.2테라피 | W13: =IFERROR(VLOOKUP(A13,'[1]CPNP,SCPN 허가번호 리스트(필터 재정비)'!$C:$J,8,0),0) -> 단종 및 내용물 AD 예정 | X13: =IFERROR(VLOOKUP(A13,[2]수록현황_260107!$D:$I,6,0),0) -> 허가 유효
A14: 111080749 | B14: 111080634 | C14: 8809820699270 | D14: ET.0.2TherapyAirMask_Lemon_20ml('23) | E14: 20 | F14: ML | G14: 1500 | H14: =ROUNDUP(G14*$H$1,-1) -> 750 | I14: =H14/1340 -> 0.55970149 | J14: 50 | K14: 300 | L14: 18000 | M14: 109*4*170MM | N14: =VLOOKUP(A14,[3]Sheet2!$A:$J,10,0) -> 생산 중지예정 | O14: 36 | P14: 3307909000 | Q14: 455*190*260mm | R14: 9.7 | S14: 30 | U14: 1364 | V14: 0.2테라피 | W14: =IFERROR(VLOOKUP(A14,'[1]CPNP,SCPN 허가번호 리스트(필터 재정비)'!$C:$J,8,0),0) -> 0 | X14: =IFERROR(VLOOKUP(A14,[2]수록현황_260107!$D:$I,6,0),0) -> 허가 유효
A15: 111080750 | B15: 111080637 | C15: 8809820699287 | D15: ET.0.2TherapyAirMask_HyaluronicAcid_20ml | E15: 20 | F15: ML | G15: 1500 | H15: =ROUNDUP(G15*$H$1,-1) -> 750 | I15: =H15/1340 -> 0.55970149 | J15: 50 | K15: 300 | L15: 18000 | M15: 109*4*170MM | N15: =VLOOKUP(A15,[3]Sheet2!$A:$J,10,0) -> 생산 중지예정 | O15: 36 | P15: 3307909000 | Q15: 455*190*260mm | R15: 9.7 | S15: 30 | U15: 1364 | V15: 0.2테라피 | W15: =IFERROR(VLOOKUP(A15,'[1]CPNP,SCPN 허가번호 리스트(필터 재정비)'!$C:$J,8,0),0) -> 단종 및 내용물 AD 예정 | X15: =IFERROR(VLOOKUP(A15,[2]수록현황_260107!$D:$I,6,0),0) -> 허가 유효
A16: 111080751 | B16: 111080639 | C16: 8809820699294 | D16: ET.0.2TherapyAirMask_ManukaHoney_20ml('2 | E16: 20 | F16: ML | G16: 1500 | H16: =ROUNDUP(G16*$H$1,-1) -> 750 | I16: =H16/1340 -> 0.55970149 | J16: 50 | K16: 300 | L16: 18000 | M16: 109*4*170MM | N16: =VLOOKUP(A16,[3]Sheet2!$A:$J,10,0) -> 생산 중지예정 | O16: 36 | P16: 3307909000 | Q16: 455*190*260mm | R16: 9.7 | S16: 30 | U16: 1364 | V16: 0.2테라피 | W16: =IFERROR(VLOOKUP(A16,'[1]CPNP,SCPN 허가번호 리스트(필터 재정비)'!$C:$J,8,0),0) -> 0 | X16: =IFERROR(VLOOKUP(A16,[2]수록현황_260107!$D:$I,6,0),0) -> 허가 유효
A17: 111080752 | B17: 111080640 | C17: 8809820699300 | D17: ET.0.2TherapyAirMask_Collagen_20ml('23) | E17: 20 | F17: ML | G17: 1500 | H17: =ROUNDUP(G17*$H$1,-1) -> 750 | I17: =H17/1340 -> 0.55970149 | J17: 50 | K17: 300 | L17: 18000 | M17: 109*4*170MM | N17: =VLOOKUP(A17,[3]Sheet2!$A:$J,10,0) -> 생산 중지예정 | O17: 36 | P17: 3307904000 | Q17: 455*190*260mm | R17: 9.7 | S17: 30 | U17: 1364 | V17: 0.2테라피 | W17: =IFERROR(VLOOKUP(A17,'[1]CPNP,SCPN 허가번호 리스트(필터 재정비)'!$C:$J,8,0),0) -> 단종 및 내용물 AD 예정 | X17: =IFERROR(VLOOKUP(A17,[2]수록현황_260107!$D:$I,6,0),0) -> 허가 유효
A18: 111080753 | B18: 111080641 | C18: 8809820699317 | D18: ET.0.2TherapyAirMask_Snail_20ml('23) | E18: 20 | F18: ML | G18: 1500 | H18: =ROUNDUP(G18*$H$1,-1) -> 750 | I18: =H18/1340 -> 0.55970149 | J18: 50 | K18: 300 | L18: 18000 | M18: 109*4*170MM | N18: =VLOOKUP(A18,[3]Sheet2!$A:$J,10,0) -> 생산 중지예정 | O18: 36 | P18: 3307904000 | Q18: 455*190*260mm | R18: 9.7 | S18: 30 | U18: 1364 | V18: 0.2테라피 | W18: =IFERROR(VLOOKUP(A18,'[1]CPNP,SCPN 허가번호 리스트(필터 재정비)'!$C:$J,8,0),0) -> 단종 및 내용물 AD 예정 | X18: =IFERROR(VLOOKUP(A18,[2]수록현황_260107!$D:$I,6,0),0) -> 허가 유효
A19: 111080754 | B19: 111080642 | C19: 8809820699324 | D19: ET.0.2TherapyAirMask_Ceramide_20ml('23) | E19: 20 | F19: ML | G19: 1500 | H19: =ROUNDUP(G19*$H$1,-1) -> 750 | I19: =H19/1340 -> 0.55970149 | J19: 50 | K19: 300 | L19: 18000 | M19: 109*4*170MM | N19: =VLOOKUP(A19,[3]Sheet2!$A:$J,10,0) -> 생산 중지예정 | O19: 36 | P19: 3307909000 | Q19: 455*190*260mm | R19: 9.7 | S19: 30 | U19: 1364 | V19: 0.2테라피 | W19: =IFERROR(VLOOKUP(A19,'[1]CPNP,SCPN 허가번호 리스트(필터 재정비)'!$C:$J,8,0),0) -> 단종 및 내용물 AD 예정 | X19: =IFERROR(VLOOKUP(A19,[2]수록현황_260107!$D:$I,6,0),0) -> 허가 유효
A20: 110090578 | B20: 110090514 | C20: 8809820692288 | D20: ET.AC.C. Pink Spot 15ml(24) | E20: 15 | F20: ML | G20: 14000 | H20: =ROUNDUP(G20*$H$1,-1) -> 7000 | I20: =H20/1340 -> 5.2238806 | J20: 6 | K20: 132 | L20: 6336 | M20: 34*34*72MM | N20: =VLOOKUP(A20,[3]Sheet2!$A:$J,10,0) -> 러닝 본품 D (상위 95~99%) | O20: 36 | P20: 3304991000 | Q20: 394*324*195mm | R20: 6.904 | S20: 47 | U20: 12727 | V20: AC클린업 | W20: =IFERROR(VLOOKUP(A20,'[1]CPNP,SCPN 허가번호 리스트(필터 재정비)'!$C:$J,8,0),0) -> 운영 | X20: =IFERROR(VLOOKUP(A20,[2]수록현황_260107!$D:$I,6,0),0) -> 0
A21: 111080781 | B21: 111080712 | C21: 8809820700181 | D21: ET.AC.C. Cleansing Foam 150ml(24) | E21: 150 | F21: ML | G21: 9000 | H21: =ROUNDUP(G21*$H$1,-1) -> 4500 | I21: =H21/1340 -> 3.358209 | J21: 6 | K21: 48 | L21: 2304 | M21: 70*44*176MM | N21: =VLOOKUP(A21,[3]Sheet2!$A:$J,10,0) -> 러닝 본품 E (상위 99~100%) | O21: 36 | P21: 3401300000 | Q21: 432*305*205mm | R21: 9.628 | S21: 186 | U21: 8182 | V21: AC클린업 | W21: =IFERROR(VLOOKUP(A21,'[1]CPNP,SCPN 허가번호 리스트(필터 재정비)'!$C:$J,8,0),0) -> 운영 | X21: =IFERROR(VLOOKUP(A21,[2]수록현황_260107!$D:$I,6,0),0) -> 0
A22: 650003989 | C22: 8809820706350 | D22: ET.WHAT'S IN MY EYES DIYpalette (4) | E22: 1 | F22: EA | G22: 6000 | H22: =ROUNDUP(G22*$H$1,-1) -> 3000 | I22: =H22/1340 -> 2.238806 | J22: 5 | K22: 150 | L22: 8400 | M22: 71*72*15MM | N22: =VLOOKUP(A22,[3]Sheet2!$A:$J,10,0) -> 러닝 본품 C (상위 80~95%) | O22: 0 | P22: 3926909000 | Q22: 300*430*210mm | R22: 7.2011 | S22: 48 | U22: 5455 | V22: DIY팔레트 | W22: =IFERROR(VLOOKUP(A22,'[1]CPNP,SCPN 허가번호 리스트(필터 재정비)'!$C:$J,8,0),0) -> 0 | X22: =IFERROR(VLOOKUP(A22,[2]수록현황_260107!$D:$I,6,0),0) -> 0
A23: 650003990 | C23: 8809820706367 | D23: ET.WHAT'S IN MY EYES DIYpalette (6) | E23: 1 | F23: EA | G23: 8000 | H23: =ROUNDUP(G23*$H$1,-1) -> 4000 | I23: =H23/1340 -> 2.9850746 | J23: 6 | K23: 72 | L23: 4032 | M23: 73*101*16MM | N23: =VLOOKUP(A23,[3]Sheet2!$A:$J,10,0) -> 러닝 본품 E (상위 99~100%) | O23: 0 | P23: 3926909000 | Q23: 300*430*210mm | R23: 4.6091 | S23: 64 | U23: 7273 | V23: DIY팔레트 | W23: =IFERROR(VLOOKUP(A23,'[1]CPNP,SCPN 허가번호 리스트(필터 재정비)'!$C:$J,8,0),0) -> 0 | X23: =IFERROR(VLOOKUP(A23,[2]수록현황_260107!$D:$I,6,0),0) -> 0
A24: 650003581 | B24: 650003186 | C24: 8809820699669 | D24: ET.CONTOUR POWDER 01Creator(23) | E24: 10 | F24: G | G24: 20000 | H24: =ROUNDUP(G24*$H$1,-1) -> 10000 | I24: =H24/1340 -> 7.4626866 | J24: 6 | K24: 108 | L24: 4320 | M24: 107*60*21MM(외) | N24: =VLOOKUP(A24,[3]Sheet2!$A:$J,10,0) -> 러닝 본품 B (상위 50~80%) | O24: 36 | P24: 3304911000 | Q24: 394*324*250mm | R24: 10.42 | S24: 90 | U24: 18182 | V24: 그림자쉐딩23 | W24: =IFERROR(VLOOKUP(A24,'[1]CPNP,SCPN 허가번호 리스트(필터 재정비)'!$C:$J,8,0),0) -> 0 | X24: =IFERROR(VLOOKUP(A24,[2]수록현황_260107!$D:$I,6,0),0) -> 0
A25: 650003583 | B25: 650003446 | C25: 8809820699683 | D25: ET.CONTOUR POWDER 03(23) | E25: 10 | F25: G | G25: 20000 | H25: =ROUNDUP(G25*$H$1,-1) -> 10000 | I25: =H25/1340 -> 7.4626866 | J25: 6 | K25: 108 | L25: 4320 | M25: 107*60*21MM(외) | N25: =VLOOKUP(A25,[3]Sheet2!$A:$J,10,0) -> 러닝 본품 B (상위 50~80%) | O25: 36 | P25: 3304911000 | Q25: 394*324*250mm | R25: 10.42 | S25: 90 | U25: 18182 | V25: 그림자쉐딩23 | W25: =IFERROR(VLOOKUP(A25,'[1]CPNP,SCPN 허가번호 리스트(필터 재정비)'!$C:$J,8,0),0) -> 0 | X25: =IFERROR(VLOOKUP(A25,[2]수록현황_260107!$D:$I,6,0),0) -> 0
A26: 650003192 | C26: 8809668024982 | D26: ET.Contour Powder Brush 01 | E26: 1 | F26: EA | G26: 12000 | H26: =ROUNDUP(G26*$H$1,-1) -> 6000 | I26: =H26/1340 -> 4.4776119 | J26: 6 | K26: 72 | L26: 1440 | M26: 210*65*35MM | N26: =VLOOKUP(A26,[3]Sheet2!$A:$J,10,0) -> 러닝 본품 D (상위 95~99%) | O26: 60 | P26: 9603300000 | Q26: 460*440*260mm | R26: 5.02 | S26: 60 | U26: 10909 | V26: 그림자쉐딩도구류 | W26: =IFERROR(VLOOKUP(A26,'[1]CPNP,SCPN 허가번호 리스트(필터 재정비)'!$C:$J,8,0),0) -> 0 | X26: =IFERROR(VLOOKUP(A26,[2]수록현황_260107!$D:$I,6,0),0) -> 0
A27: 650003193 | C27: 8809668024999 | D27: ET.Contour Powder Brush 02 | E27: 1 | F27: EA | G27: 7000 | H27: =ROUNDUP(G27*$H$1,-1) -> 3500 | I27: =H27/1340 -> 2.6119403 | J27: 10 | K27: 160 | L27: 3200 | M27: 185*40*20MM | N27: =VLOOKUP(A27,[3]Sheet2!$A:$J,10,0) -> 러닝 본품 C (상위 80~95%) | O27: 60 | P27: 9603300000 | Q27: 410*380*250mm | R27: 4.7 | S27: 25 | U27: 6364 | V27: 그림자쉐딩도구류 | W27: =IFERROR(VLOOKUP(A27,'[1]CPNP,SCPN 허가번호 리스트(필터 재정비)'!$C:$J,8,0),0) -> 0 | X27: =IFERROR(VLOOKUP(A27,[2]수록현황_260107!$D:$I,6,0),0) -> 0
A28: 650003194 | C28: 8809668025002 | D28: ET.Contour Powder Brush 03 | E28: 1 | F28: EA | G28: 5000 | H28: =ROUNDUP(G28*$H$1,-1) -> 2500 | I28: =H28/1340 -> 1.8656716 | J28: 10 | K28: 160 | L28: 3200 | M28: 185*40*20MM | N28: =VLOOKUP(A28,[3]Sheet2!$A:$J,10,0) -> 러닝 본품 C (상위 80~95%) | O28: 60 | P28: 9603300000 | Q28: 410*380*250mm | R28: 4.7 | S28: 25 | U28: 4545 | V28: 그림자쉐딩도구류 | W28: =IFERROR(VLOOKUP(A28,'[1]CPNP,SCPN 허가번호 리스트(필터 재정비)'!$C:$J,8,0),0) -> 0 | X28: =IFERROR(VLOOKUP(A28,[2]수록현황_260107!$D:$I,6,0),0) -> 0
A29: 650003643 | C29: 8809820691793 | D29: ET. Glaze Plump Gloss #1 4g | E29: 4 | F29: G | G29: 13000 | H29: =ROUNDUP(G29*$H$1,-1) -> 6500 | I29: =H29/1340 -> 4.8507463 | J29: 6 | K29: 216 | L29: 15552 | M29: 20*20*97MM | N29: =VLOOKUP(A29,[3]Sheet2!$A:$J,10,0) -> 생산 중지예정 | O29: 24 | P29: 3304109000 | Q29: 432*305*135mm | R29: 8.044 | S29: 34 | U29: 11818 | V29: 글레이즈플럼프 | W29: =IFERROR(VLOOKUP(A29,'[1]CPNP,SCPN 허가번호 리스트(필터 재정비)'!$C:$J,8,0),0) -> 0 | X29: =IFERROR(VLOOKUP(A29,[2]수록현황_260107!$D:$I,6,0),0) -> 허가 유효
A30: 650003644 | C30: 8809820693377 | D30: ET. Glaze Plump Gloss #2 4g | E30: 4 | F30: G | G30: 13000 | H30: =ROUNDUP(G30*$H$1,-1) -> 6500 | I30: =H30/1340 -> 4.8507463 | J30: 6 | K30: 216 | L30: 15552 | M30: 20*20*97MM | N30: =VLOOKUP(A30,[3]Sheet2!$A:$J,10,0) -> 생산 중지예정 | O30: 24 | P30: 3304109000 | Q30: 432*305*135mm | R30: 8.044 | S30: 34 | U30: 11818 | V30: 글레이즈플럼프 | W30: =IFERROR(VLOOKUP(A30,'[1]CPNP,SCPN 허가번호 리스트(필터 재정비)'!$C:$J,8,0),0) -> 0 | X30: =IFERROR(VLOOKUP(A30,[2]수록현황_260107!$D:$I,6,0),0) -> 허가 유효
A31: 650003645 | C31: 8809820693384 | D31: ET. Glaze Plump Gloss #3 4g | E31: 4 | F31: G | G31: 13000 | H31: =ROUNDUP(G31*$H$1,-1) -> 6500 | I31: =H31/1340 -> 4.8507463 | J31: 6 | K31: 216 | L31: 15552 | M31: 20*20*97MM | N31: =VLOOKUP(A31,[3]Sheet2!$A:$J,10,0) -> 생산 중지예정 | O31: 24 | P31: 3304109000 | Q31: 432*305*135mm | R31: 8.044 | S31: 34 | U31: 11818 | V31: 글레이즈플럼프 | W31: =IFERROR(VLOOKUP(A31,'[1]CPNP,SCPN 허가번호 리스트(필터 재정비)'!$C:$J,8,0),0) -> 0 | X31: =IFERROR(VLOOKUP(A31,[2]수록현황_260107!$D:$I,6,0),0) -> 허가 유효
A32: 650003468 | C32: 8809820693063 | D32: ET. Glow Fixing Tint #1 pure coral 3.8g | E32: 3.8 | F32: G | G32: 14000 | H32: =ROUNDUP(G32*$H$1,-1) -> 7000 | I32: =H32/1340 -> 5.2238806 | J32: 6 | K32: 96 | L32: 10368 | M32: 26*23*113MM(외) | N32: =VLOOKUP(A32,[3]Sheet2!$A:$J,10,0) -> 생산 중지예정 | O32: 36 | P32: 3304109000 | Q32: 397*213*135mm | R32: 4.348 | S32: 38 | U32: 12727 | V32: 글로우픽싱틴트 | W32: =IFERROR(VLOOKUP(A32,'[1]CPNP,SCPN 허가번호 리스트(필터 재정비)'!$C:$J,8,0),0) -> 운영 | X32: =IFERROR(VLOOKUP(A32,[2]수록현황_260107!$D:$I,6,0),0) -> 허가 유효
A33: 650003469 | C33: 8809820693070 | D33: ET. Glow Fixing Tint #6 P.B 3.8g_착인 | E33: 3.8 | F33: G | G33: 14000 | H33: =ROUNDUP(G33*$H$1,-1) -> 7000 | I33: =H33/1340 -> 5.2238806 | J33: 6 | K33: 96 | L33: 10368 | M33: 26*23*113MM(외) | N33: =VLOOKUP(A33,[3]Sheet2!$A:$J,10,0) -> 생산 중지예정 | O33: 36 | P33: 3304109000 | Q33: 397*213*135mm | R33: 4.348 | S33: 38 | U33: 12727 | V33: 글로우픽싱틴트 | W33: =IFERROR(VLOOKUP(A33,'[1]CPNP,SCPN 허가번호 리스트(필터 재정비)'!$C:$J,8,0),0) -> 운영 | X33: =IFERROR(VLOOKUP(A33,[2]수록현황_260107!$D:$I,6,0),0) -> 허가 유효
A34: 650003470 | C34: 8809820693087 | D34: ET. Glow Fixing Tint #7 C.F 3.8g_착인 | E34: 3.8 | F34: G | G34: 14000 | H34: =ROUNDUP(G34*$H$1,-1) -> 7000 | I34: =H34/1340 -> 5.2238806 | J34: 6 | K34: 96 | L34: 10368 | M34: 26*23*113MM(외) | N34: =VLOOKUP(A34,[3]Sheet2!$A:$J,10,0) -> 러닝 본품 D (상위 95~99%) | O34: 36 | P34: 3304109000 | Q34: 397*213*135mm | R34: 4.348 | S34: 38 | U34: 12727 | V34: 글로우픽싱틴트 | W34: =IFERROR(VLOOKUP(A34,'[1]CPNP,SCPN 허가번호 리스트(필터 재정비)'!$C:$J,8,0),0) -> 운영 | X34: =IFERROR(VLOOKUP(A34,[2]수록현황_260107!$D:$I,6,0),0) -> 허가 유효
A35: 650003471 | C35: 8809820693094 | D35: ET. Glow Fixing Tint #2 mellow pink 3.8g | E35: 3.8 | F35: G | G35: 14000 | H35: =ROUNDUP(G35*$H$1,-1) -> 7000 | I35: =H35/1340 -> 5.2238806 | J35: 6 | K35: 96 | L35: 10368 | M35: 26*23*113MM(외) | N35: =VLOOKUP(A35,[3]Sheet2!$A:$J,10,0) -> 러닝 본품 C (상위 80~95%) | O35: 36 | P35: 3304109000 | Q35: 397*213*135mm | R35: 4.348 | S35: 38 | U35: 12727 | V35: 글로우픽싱틴트 | W35: =IFERROR(VLOOKUP(A35,'[1]CPNP,SCPN 허가번호 리스트(필터 재정비)'!$C:$J,8,0),0) -> 운영 | X35: =IFERROR(VLOOKUP(A35,[2]수록현황_260107!$D:$I,6,0),0) -> 허가 유효
A36: 650003472 | C36: 8809820693100 | D36: ET. Glow Fixing Tint #3 Dewy Fig 3.8g | E36: 3.8 | F36: G | G36: 14000 | H36: =ROUNDUP(G36*$H$1,-1) -> 7000 | I36: =H36/1340 -> 5.2238806 | J36: 6 | K36: 96 | L36: 10368 | M36: 26*23*113MM(외) | N36: =VLOOKUP(A36,[3]Sheet2!$A:$J,10,0) -> 러닝 본품 C (상위 80~95%) | O36: 36 | P36: 3304109000 | Q36: 397*213*135mm | R36: 4.348 | S36: 38 | U36: 12727 | V36: 글로우픽싱틴트 | W36: =IFERROR(VLOOKUP(A36,'[1]CPNP,SCPN 허가번호 리스트(필터 재정비)'!$C:$J,8,0),0) -> 운영 | X36: =IFERROR(VLOOKUP(A36,[2]수록현황_260107!$D:$I,6,0),0) -> 허가 유효
A37: 650003473 | C37: 8809820693605 | D37: ET. Glow Fixing Tint #4 C.Red 3.8g | E37: 3.8 | F37: G | G37: 14000 | H37: =ROUNDUP(G37*$H$1,-1) -> 7000 | I37: =H37/1340 -> 5.2238806 | J37: 6 | K37: 96 | L37: 10368 | M37: 26*23*113MM(외) | N37: =VLOOKUP(A37,[3]Sheet2!$A:$J,10,0) -> 러닝 본품 C (상위 80~95%) | O37: 36 | P37: 3304109000 | Q37: 397*213*135mm | R37: 4.348 | S37: 38 | U37: 12727 | V37: 글로우픽싱틴트 | W37: =IFERROR(VLOOKUP(A37,'[1]CPNP,SCPN 허가번호 리스트(필터 재정비)'!$C:$J,8,0),0) -> 운영 | X37: =IFERROR(VLOOKUP(A37,[2]수록현황_260107!$D:$I,6,0),0) -> 허가 유효
A38: 650003486 | C38: 8809820694008 | D38: ET. Glow Fixing Tint #5 Mauvement 3.8g | E38: 3.8 | F38: G | G38: 14000 | H38: =ROUNDUP(G38*$H$1,-1) -> 7000 | I38: =H38/1340 -> 5.2238806 | J38: 6 | K38: 96 | L38: 10368 | M38: 26*23*113MM(외) | N38: =VLOOKUP(A38,[3]Sheet2!$A:$J,10,0) -> 러닝 본품 C (상위 80~95%) | O38: 36 | P38: 3304109000 | Q38: 397*213*135mm | R38: 4.348 | S38: 38 | U38: 12727 | V38: 글로우픽싱틴트 | W38: =IFERROR(VLOOKUP(A38,'[1]CPNP,SCPN 허가번호 리스트(필터 재정비)'!$C:$J,8,0),0) -> 운영 | X38: =IFERROR(VLOOKUP(A38,[2]수록현황_260107!$D:$I,6,0),0) -> 허가 유효
A39: 650003588 | B39: 650003524 | C39: 8809820698723 | D39: ET. Glow Fixing Tint #8 R.S 3.8g | E39: 3.8 | F39: G | G39: 14000 | H39: =ROUNDUP(G39*$H$1,-1) -> 7000 | I39: =H39/1340 -> 5.2238806 | J39: 6 | K39: 216 | L39: 15552 | M39: 20*20*111MM | N39: =VLOOKUP(A39,[3]Sheet2!$A:$J,10,0) -> 생산 중지예정 | O39: 36 | P39: 3304109000 | Q39: 432*305*135mm | R39: 8.908 | S39: 38 | U39: 12727 | V39: 글로우픽싱틴트 | W39: =IFERROR(VLOOKUP(A39,'[1]CPNP,SCPN 허가번호 리스트(필터 재정비)'!$C:$J,8,0),0) -> 0 | X39: =IFERROR(VLOOKUP(A39,[2]수록현황_260107!$D:$I,6,0),0) -> 0
A40: 650003589 | B40: 650003535 | C40: 8809820698730 | D40: ET.Glow Fixing Tint #9 L.B 3.8g | E40: 3.8 | F40: G | G40: 14000 | H40: =ROUNDUP(G40*$H$1,-1) -> 7000 | I40: =H40/1340 -> 5.2238806 | J40: 6 | K40: 216 | L40: 15552 | M40: 20*20*111MM | N40: =VLOOKUP(A40,[3]Sheet2!$A:$J,10,0) -> 생산 중지예정 | O40: 36 | P40: 3304109000 | Q40: 432*305*135mm | R40: 8.908 | S40: 38 | U40: 12727 | V40: 글로우픽싱틴트 | W40: =IFERROR(VLOOKUP(A40,'[1]CPNP,SCPN 허가번호 리스트(필터 재정비)'!$C:$J,8,0),0) -> 0 | X40: =IFERROR(VLOOKUP(A40,[2]수록현황_260107!$D:$I,6,0),0) -> 0
...
