Workbook

Sheet Как заполнять
A1: Как вести этот файл
A2: Желтое — вводим руками. Зеленое — считается. Файл ведется во время погрузки, а не после отправки.
A4: № | B4: Правило | C4: Почему так
A5: 1 | B5: Состояние ставим при погрузке, не после | C5: Позицию все равно берут в руки и кладут в ящик — тогда и видно, новая она или б/у. В учете состояние проставлено только у 54 позиций из 810, по остальным его просто нет. Заполнить потом по памяти не получится.
A6: 2 | B6: Новое и б/у не смешиваем в одном месте | C6: Покупатель принимает груз по упаковочному листу. Если в ящике лежит и новое, и б/у, спор о состоянии придет на весь ящик.
A7: 3 | B7: Сначала расходы, потом цены | C7: Доставка разносится от суммы на листе расходов. Пока там нули, колонка «Доставка на ед.» будет нулевой, и цена с доставкой совпадет с ценой товара.
A8: 4 | B8: Разносим по весу | C8: За контейнер платят за тонны, поэтому доставка ложится на вес. На задвижке Ду250 это будут тысячи рублей на штуку, на штуцерном клапане — рубли. Разнести поровну на штуку значит завысить цену мелочи и занизить цену тяжелой арматуры.
A9: 5 | B9: Вес можно заменить на фактический | C9: Колонка «Вес ед.» желтая: там стоит справочная масса с погрешностью около трети. Взвесили место — впишите факт, разнесение пересчитается.
A10: 6 | B10: Отгружено, а не числится | C10: Колонка «Числится» — то, что стоит в учете на 16.06.2025 и не подтверждено инвентаризацией. Считаем по колонке «Отгружено»: сколько реально положили в контейнер.
A11: 7 | B11: Цена с доставкой — это не цена продажи | C11: Это то, во что позиция обошлась на складе в Петербурге. Цену покупателю ставим от нее, иначе тяжелая арматура уедет в минус.
A12: 8 | B12: Каждое место — свой номер | C12: Номер места в отгрузке должен совпадать с биркой на ящике и строкой упаковочного листа. Иначе принимать груз придется вскрытием всего подряд.

Sheet Расходы и доставка
A1: Расходы на отгрузку и как они ложатся на товар
A2: Желтые ячейки заполняем сами. Все остальное считается. Пока расходы не введены, доставка на единицу будет нулевой.
A4: Расход | B4: Сумма, руб | C4: Комментарий
A5: Контейнер: фрахт Владивосток — Петербург
A6: Автодоставка до контейнера во Владивостоке
A7: Погрузка и выгрузка, такелаж
A8: Тара: поддоны, доска, ящики
A9: Упаковка: стрейч, лента, фанера на фланцы
A10: Экспедирование и документы
A11: Страхование груза
A12: Прочие расходы
A13: ИТОГО расходов на отгрузку | B13: =SUM(B5:B12)
A15: Как разносим на позиции | B15: по весу | C15: За контейнер платят за тонны, поэтому по умолчанию по весу
A17: Что набралось в отгрузке
A19: Вес всего, кг | B19: =SUM('Отгрузка'!N5:N149)
A20: Объем всего, м³ | B20: =SUM('Отгрузка'!O5:O149)
A21: Штук всего | B21: =SUM('Отгрузка'!L5:L149)
A22: Стоимость товара, руб | B22: =SUM('Отгрузка'!T5:T149)
A24: Сколько стоит перевозка
A25: Доставка на килограмм, руб | B25: =IFERROR(B13/B19,0)
A26: Доставка на штуку в среднем, руб | B26: =IFERROR(B13/B21,0)
A27: Доставка в процентах от стоимости товара | B27: =IFERROR(B13/B22,0)
A28: Товар с доставкой, руб | B28: =B22+B13

Sheet Отгрузка
A1: Отгрузка в Санкт-Петербург: что грузим и почем выходит
A2: Желтые колонки заполняем при погрузке. Состояние ставим на месте: в учете оно проставлено только у части позиций. Зеленые колонки считаются сами.
A4: № | B4: Очередь | C4: Ярус | D4: Тип | E4: Диаметр | F4: Наименование | G4: Чертеж | H4: Состояние | I4: Комплектность | J4: Материал | K4: Числится, шт | L4: Отгружено, шт | M4: Вес ед., кг | N4: Вес всего, кг | O4: Объем всего, м³ | P4: Доля в отгрузке | Q4: Доставка на позицию, руб | R4: Доставка на ед., руб | S4: Цена за ед., руб | T4: Сумма позиции, руб | U4: Цена с доставкой за ед., руб | V4: Доставка в цене, % | W4: № места | X4: Локация | Y4: Примечание
A5: 1 | B5: 1. Клинкет Ду250, Ду300, Ду350, бронза и латунь | C5: Ярус 1, на настил | D5: клинкет (задвижка) | E5: Ду250 | F5: Клинкет Ду 250 | I5: Комплект | J5: проверить: везем бронзу и латунь | K5: 2 | L5: 2 | M5: 220 | N5: =L5*M5 | O5: 0.5 | P5: =IFERROR(IF('Расходы и доставка'!$B$15="по весу",N5/'Расходы и доставка'!$B$19,IF('Расходы и доставка'!$B$15="по объему",O5/'Расходы и доставка'!$B$20,IF('Расходы и доставка'!$B$15="поровну на штуку",L5/'Расходы и доставка'!$B$21,T5/'Расходы и доставка'!$B$22))),0) | Q5: =P5*'Расходы и доставка'!$B$13 | R5: =IFERROR(Q5/L5,0) | S5: 200000 | T5: =L5*S5 | U5: =S5+R5 | V5: =IFERROR(R5/S5,"") | X5: Фойе
A6: 2 | B6: 1. Клинкет Ду250, Ду300, Ду350, бронза и латунь | C6: Ярус 1, на настил | D6: клинкет (задвижка) | E6: Ду250 | F6: Клинкет Ду 250 не комплект | I6: Не комплект | J6: проверить: везем бронзу и латунь | K6: 2 | L6: 2 | M6: 220 | N6: =L6*M6 | O6: 0.5 | P6: =IFERROR(IF('Расходы и доставка'!$B$15="по весу",N6/'Расходы и доставка'!$B$19,IF('Расходы и доставка'!$B$15="по объему",O6/'Расходы и доставка'!$B$20,IF('Расходы и доставка'!$B$15="поровну на штуку",L6/'Расходы и доставка'!$B$21,T6/'Расходы и доставка'!$B$22))),0) | Q6: =P6*'Расходы и доставка'!$B$13 | R6: =IFERROR(Q6/L6,0) | S6: 200000 | T6: =L6*S6 | U6: =S6+R6 | V6: =IFERROR(R6/S6,"") | X6: Фойе
A7: 3 | B7: 1. Клинкет Ду250, Ду300, Ду350, бронза и латунь | C7: Ярус 1, на настил | D7: клинкет (задвижка) | E7: Ду300 | F7: Клинкет Ду 300 | I7: Комплект | J7: проверить: везем бронзу и латунь | K7: 16 | L7: 16 | M7: 300 | N7: =L7*M7 | O7: 5.6 | P7: =IFERROR(IF('Расходы и доставка'!$B$15="по весу",N7/'Расходы и доставка'!$B$19,IF('Расходы и доставка'!$B$15="по объему",O7/'Расходы и доставка'!$B$20,IF('Расходы и доставка'!$B$15="поровну на штуку",L7/'Расходы и доставка'!$B$21,T7/'Расходы и доставка'!$B$22))),0) | Q7: =P7*'Расходы и доставка'!$B$13 | R7: =IFERROR(Q7/L7,0) | S7: 250000 | T7: =L7*S7 | U7: =S7+R7 | V7: =IFERROR(R7/S7,"") | X7: Фойе
A8: 4 | B8: 1. Клинкет Ду250, Ду300, Ду350, бронза и латунь | C8: Ярус 1, на настил | D8: клинкет (задвижка) | E8: Ду350 | F8: Клинкет Ду 350 | I8: Комплект | J8: проверить: везем бронзу и латунь | K8: 1 | L8: 1 | M8: 400 | N8: =L8*M8 | O8: 0.45 | P8: =IFERROR(IF('Расходы и доставка'!$B$15="по весу",N8/'Расходы и доставка'!$B$19,IF('Расходы и доставка'!$B$15="по объему",O8/'Расходы и доставка'!$B$20,IF('Расходы и доставка'!$B$15="поровну на штуку",L8/'Расходы и доставка'!$B$21,T8/'Расходы и доставка'!$B$22))),0) | Q8: =P8*'Расходы и доставка'!$B$13 | R8: =IFERROR(Q8/L8,0) | S8: 300000 | T8: =L8*S8 | U8: =S8+R8 | V8: =IFERROR(R8/S8,"") | X8: Фойе
A9: 5 | B9: 1. Клинкет Ду250, Ду300, Ду350, бронза и латунь | C9: Ярус 1, на настил | D9: клинкет (задвижка) | E9: Ду250 | F9: Задвижка клинкетная Ду 250 | I9: Комплект | J9: проверить: везем бронзу и латунь | K9: 17 | L9: 17 | M9: 220 | N9: =L9*M9 | O9: 4.25 | P9: =IFERROR(IF('Расходы и доставка'!$B$15="по весу",N9/'Расходы и доставка'!$B$19,IF('Расходы и доставка'!$B$15="по объему",O9/'Расходы и доставка'!$B$20,IF('Расходы и доставка'!$B$15="поровну на штуку",L9/'Расходы и доставка'!$B$21,T9/'Расходы и доставка'!$B$22))),0) | Q9: =P9*'Расходы и доставка'!$B$13 | R9: =IFERROR(Q9/L9,0) | S9: 150000 | T9: =L9*S9 | U9: =S9+R9 | V9: =IFERROR(R9/S9,"") | X9: Склад 1А/1Б
A10: 6 | B10: 2. Титановая арматура | C10: Ярус 4, верх | D10: клапан фланцевый | E10: Ду50 | F10: Клапан фланцевый проходной титановые Ду50Ру10 | G10: 521-182.110 | H10: Новое | I10: Комплект | J10: титан | K10: 5 | L10: 5 | M10: 14 | N10: =L10*M10 | O10: 0.06 | P10: =IFERROR(IF('Расходы и доставка'!$B$15="по весу",N10/'Расходы и доставка'!$B$19,IF('Расходы и доставка'!$B$15="по объему",O10/'Расходы и доставка'!$B$20,IF('Расходы и доставка'!$B$15="поровну на штуку",L10/'Расходы и доставка'!$B$21,T10/'Расходы и доставка'!$B$22))),0) | Q10: =P10*'Расходы и доставка'!$B$13 | R10: =IFERROR(Q10/L10,0) | T10: =L10*S10 | U10: =S10+R10 | V10: =IFERROR(R10/S10,"") | X10: Склад 2
A11: 7 | B11: 2. Титановая арматура | C11: Ярус 4, верх | D11: клапан фланцевый | E11: Ду100 | F11: Клапан фланцевый проходной титановые Ду100Ру10 | G11: 521-182.116 | H11: Новое | I11: Комплект | J11: титан | K11: 1 | L11: 1 | M11: 40 | N11: =L11*M11 | O11: 0.045 | P11: =IFERROR(IF('Расходы и доставка'!$B$15="по весу",N11/'Расходы и доставка'!$B$19,IF('Расходы и доставка'!$B$15="по объему",O11/'Расходы и доставка'!$B$20,IF('Расходы и доставка'!$B$15="поровну на штуку",L11/'Расходы и доставка'!$B$21,T11/'Расходы и доставка'!$B$22))),0) | Q11: =P11*'Расходы и доставка'!$B$13 | R11: =IFERROR(Q11/L11,0) | T11: =L11*S11 | U11: =S11+R11 | V11: =IFERROR(R11/S11,"") | X11: Склад 2
A12: 8 | B12: 3. Остальная бронза и латунь | C12: Ярус 3, ящики | D12: клапан фланцевый | E12: Ду25 | F12: Клапан фланцевый угловой Ду25 | G12: 521-3М539 | I12: Комплект | J12: бронза/латунь | K12: 15 | L12: 15 | M12: 5 | N12: =L12*M12 | O12: 0.045 | P12: =IFERROR(IF('Расходы и доставка'!$B$15="по весу",N12/'Расходы и доставка'!$B$19,IF('Расходы и доставка'!$B$15="по объему",O12/'Расходы и доставка'!$B$20,IF('Расходы и доставка'!$B$15="поровну на штуку",L12/'Расходы и доставка'!$B$21,T12/'Расходы и доставка'!$B$22))),0) | Q12: =P12*'Расходы и доставка'!$B$13 | R12: =IFERROR(Q12/L12,0) | S12: 9600 | T12: =L12*S12 | U12: =S12+R12 | V12: =IFERROR(R12/S12,"") | X12: Склад 3
A13: 9 | B13: 3. Остальная бронза и латунь | C13: Ярус 3, ящики | D13: клапан фланцевый | E13: Ду40 | F13: Клапан фланцевый угловой Ду40 Ру25 | G13: 521-01.200 | I13: Комплект | J13: бронза/латунь | K13: 1 | L13: 1 | M13: 10 | N13: =L13*M13 | O13: 0.008 | P13: =IFERROR(IF('Расходы и доставка'!$B$15="по весу",N13/'Расходы и доставка'!$B$19,IF('Расходы и доставка'!$B$15="по объему",O13/'Расходы и доставка'!$B$20,IF('Расходы и доставка'!$B$15="поровну на штуку",L13/'Расходы и доставка'!$B$21,T13/'Расходы и доставка'!$B$22))),0) | Q13: =P13*'Расходы и доставка'!$B$13 | R13: =IFERROR(Q13/L13,0) | S13: 18000 | T13: =L13*S13 | U13: =S13+R13 | V13: =IFERROR(R13/S13,"") | X13: Склад 3
A14: 10 | B14: 3. Остальная бронза и латунь | C14: Ярус 3, ящики | D14: клапан фланцевый | E14: Ду50 | F14: Клапан фланцевый угловой Ду50 Ру25 | G14: СВ/Т3197-95В25050 | I14: Комплект | J14: бронза/латунь | K14: 7 | L14: 7 | M14: 14 | N14: =L14*M14 | O14: 0.084 | P14: =IFERROR(IF('Расходы и доставка'!$B$15="по весу",N14/'Расходы и доставка'!$B$19,IF('Расходы и доставка'!$B$15="по объему",O14/'Расходы и доставка'!$B$20,IF('Расходы и доставка'!$B$15="поровну на штуку",L14/'Расходы и доставка'!$B$21,T14/'Расходы и доставка'!$B$22))),0) | Q14: =P14*'Расходы и доставка'!$B$13 | R14: =IFERROR(Q14/L14,0) | S14: 22500 | T14: =L14*S14 | U14: =S14+R14 | V14: =IFERROR(R14/S14,"") | X14: Склад 3
A15: 11 | B15: 3. Остальная бронза и латунь | C15: Ярус 3, ящики | D15: клапан фланцевый | E15: Ду40 | F15: Клапан фланцевый угловой Ду40 Ру10 | G15: 522-03.202 | I15: Комплект | J15: бронза/латунь | K15: 1 | L15: 1 | M15: 10 | N15: =L15*M15 | O15: 0.008 | P15: =IFERROR(IF('Расходы и доставка'!$B$15="по весу",N15/'Расходы и доставка'!$B$19,IF('Расходы и доставка'!$B$15="по объему",O15/'Расходы и доставка'!$B$20,IF('Расходы и доставка'!$B$15="поровну на штуку",L15/'Расходы и доставка'!$B$21,T15/'Расходы и доставка'!$B$22))),0) | Q15: =P15*'Расходы и доставка'!$B$13 | R15: =IFERROR(Q15/L15,0) | S15: 16000 | T15: =L15*S15 | U15: =S15+R15 | V15: =IFERROR(R15/S15,"") | X15: Склад 3
A16: 12 | B16: 3. Остальная бронза и латунь | C16: Ярус 3, ящики | D16: клинкет (задвижка) | E16: Ду65 | F16: Задвижка клинкетная Ду65 | I16: Комплект | J16: бронза/латунь | K16: 16 | L16: 16 | M16: 18 | N16: =L16*M16 | O16: 0.32 | P16: =IFERROR(IF('Расходы и доставка'!$B$15="по весу",N16/'Расходы и доставка'!$B$19,IF('Расходы и доставка'!$B$15="по объему",O16/'Расходы и доставка'!$B$20,IF('Расходы и доставка'!$B$15="поровну на штуку",L16/'Расходы и доставка'!$B$21,T16/'Расходы и доставка'!$B$22))),0) | Q16: =P16*'Расходы и доставка'!$B$13 | R16: =IFERROR(Q16/L16,0) | S16: 27000 | T16: =L16*S16 | U16: =S16+R16 | V16: =IFERROR(R16/S16,"") | X16: Склад 3
A17: 13 | B17: 3. Остальная бронза и латунь | C17: Ярус 3, ящики | D17: клапан фланцевый | E17: Ду65 | F17: Клапан фланцевый угловой Ду65 Ру10 | G17: 522-35.4154-02 | I17: Комплект | J17: бронза/латунь | K17: 6 | L17: 6 | M17: 20 | N17: =L17*M17 | O17: 0.12 | P17: =IFERROR(IF('Расходы и доставка'!$B$15="по весу",N17/'Расходы и доставка'!$B$19,IF('Расходы и доставка'!$B$15="по объему",O17/'Расходы и доставка'!$B$20,IF('Расходы и доставка'!$B$15="поровну на штуку",L17/'Расходы и доставка'!$B$21,T17/'Расходы и доставка'!$B$22))),0) | Q17: =P17*'Расходы и доставка'!$B$13 | R17: =IFERROR(Q17/L17,0) | S17: 27000 | T17: =L17*S17 | U17: =S17+R17 | V17: =IFERROR(R17/S17,"") | X17: Склад 3
A18: 14 | B18: 3. Остальная бронза и латунь | C18: Ярус 3, ящики | D18: клапан фланцевый | E18: Ду65 | F18: Клапан фланцевый угловой Ду65 Ру10 | G18: 522-35.4201 | I18: Комплект | J18: бронза/латунь | K18: 3 | L18: 3 | M18: 20 | N18: =L18*M18 | O18: 0.06 | P18: =IFERROR(IF('Расходы и доставка'!$B$15="по весу",N18/'Расходы и доставка'!$B$19,IF('Расходы и доставка'!$B$15="по объему",O18/'Расходы и доставка'!$B$20,IF('Расходы и доставка'!$B$15="поровну на штуку",L18/'Расходы и доставка'!$B$21,T18/'Расходы и доставка'!$B$22))),0) | Q18: =P18*'Расходы и доставка'!$B$13 | R18: =IFERROR(Q18/L18,0) | S18: 27000 | T18: =L18*S18 | U18: =S18+R18 | V18: =IFERROR(R18/S18,"") | X18: Склад 3
A19: 15 | B19: 3. Остальная бронза и латунь | C19: Ярус 3, ящики | D19: клапан фланцевый | E19: Ду65 | F19: Клапан фланцевый угловой Ду65 Ру10 | G19: 521-03.195 | I19: Комплект | J19: бронза/латунь | K19: 12 | L19: 12 | M19: 20 | N19: =L19*M19 | O19: 0.24 | P19: =IFERROR(IF('Расходы и доставка'!$B$15="по весу",N19/'Расходы и доставка'!$B$19,IF('Расходы и доставка'!$B$15="по объему",O19/'Расходы и доставка'!$B$20,IF('Расходы и доставка'!$B$15="поровну на штуку",L19/'Расходы и доставка'!$B$21,T19/'Расходы и доставка'!$B$22))),0) | Q19: =P19*'Расходы и доставка'!$B$13 | R19: =IFERROR(Q19/L19,0) | S19: 27000 | T19: =L19*S19 | U19: =S19+R19 | V19: =IFERROR(R19/S19,"") | X19: Склад 3
A20: 16 | B20: 3. Остальная бронза и латунь | C20: Ярус 3, ящики | D20: клинкет (задвижка) | E20: Ду70 | F20: Задвижка клинкетная фланцевая Ду70 Ру6 | I20: Комплект | J20: бронза/латунь | K20: 7 | L20: 7 | M20: 22 | N20: =L20*M20 | O20: 0.154 | P20: =IFERROR(IF('Расходы и доставка'!$B$15="по весу",N20/'Расходы и доставка'!$B$19,IF('Расходы и доставка'!$B$15="по объему",O20/'Расходы и доставка'!$B$20,IF('Расходы и доставка'!$B$15="поровну на штуку",L20/'Расходы и доставка'!$B$21,T20/'Расходы и доставка'!$B$22))),0) | Q20: =P20*'Расходы и доставка'!$B$13 | R20: =IFERROR(Q20/L20,0) | S20: 27000 | T20: =L20*S20 | U20: =S20+R20 | V20: =IFERROR(R20/S20,"") | X20: Склад 3
A21: 17 | B21: 3. Остальная бронза и латунь | C21: Ярус 3, ящики | D21: клапан фланцевый | E21: Ду80 | F21: Клапан фланцевый угловой Ду80 | G21: 522-03.197 | I21: Комплект | J21: бронза/латунь | K21: 7 | L21: 7 | M21: 28 | N21: =L21*M21 | O21: 0.21 | P21: =IFERROR(IF('Расходы и доставка'!$B$15="по весу",N21/'Расходы и доставка'!$B$19,IF('Расходы и доставка'!$B$15="по объему",O21/'Расходы и доставка'!$B$20,IF('Расходы и доставка'!$B$15="поровну на штуку",L21/'Расходы и доставка'!$B$21,T21/'Расходы и доставка'!$B$22))),0) | Q21: =P21*'Расходы и доставка'!$B$13 | R21: =IFERROR(Q21/L21,0) | S21: 34000 | T21: =L21*S21 | U21: =S21+R21 | V21: =IFERROR(R21/S21,"") | X21: Склад 3
A22: 18 | B22: 3. Остальная бронза и латунь | C22: Ярус 3, ящики | D22: клинкет (задвижка) | E22: Ду80 | F22: Задвижка клинкетная фланцевая Ду80 Ру6 | I22: Комплект | J22: бронза/латунь | K22: 18 | L22: 18 | M22: 28 | N22: =L22*M22 | O22: 0.54 | P22: =IFERROR(IF('Расходы и доставка'!$B$15="по весу",N22/'Расходы и доставка'!$B$19,IF('Расходы и доставка'!$B$15="по объему",O22/'Расходы и доставка'!$B$20,IF('Расходы и доставка'!$B$15="поровну на штуку",L22/'Расходы и доставка'!$B$21,T22/'Расходы и доставка'!$B$22))),0) | Q22: =P22*'Расходы и доставка'!$B$13 | R22: =IFERROR(Q22/L22,0) | S22: 32000 | T22: =L22*S22 | U22: =S22+R22 | V22: =IFERROR(R22/S22,"") | X22: Склад 3
A23: 19 | B23: 3. Остальная бронза и латунь | C23: Ярус 3, ящики | D23: клинкет (задвижка) | E23: Ду60 | F23: Задвижка клинкетная Ду60 | I23: Комплект | J23: бронза/латунь | K23: 1 | L23: 1 | M23: 16 | N23: =L23*M23 | O23: 0.02 | P23: =IFERROR(IF('Расходы и доставка'!$B$15="по весу",N23/'Расходы и доставка'!$B$19,IF('Расходы и доставка'!$B$15="по объему",O23/'Расходы и доставка'!$B$20,IF('Расходы и доставка'!$B$15="поровну на штуку",L23/'Расходы и доставка'!$B$21,T23/'Расходы и доставка'!$B$22))),0) | Q23: =P23*'Расходы и доставка'!$B$13 | R23: =IFERROR(Q23/L23,0) | S23: 18000 | T23: =L23*S23 | U23: =S23+R23 | V23: =IFERROR(R23/S23,"") | X23: Склад 3
A24: 20 | B24: 3. Остальная бронза и латунь | C24: Ярус 2, рядом на полу | D24: клапан фланцевый | E24: Ду150 | F24: Клапан фланцевый угловой Ду150 Ру10 | I24: Комплект | J24: бронза/латунь | K24: 1 | L24: 1 | M24: 75 | N24: =L24*M24 | O24: 0.1 | P24: =IFERROR(IF('Расходы и доставка'!$B$15="по весу",N24/'Расходы и доставка'!$B$19,IF('Расходы и доставка'!$B$15="по объему",O24/'Расходы и доставка'!$B$20,IF('Расходы и доставка'!$B$15="поровну на штуку",L24/'Расходы и доставка'!$B$21,T24/'Расходы и доставка'!$B$22))),0) | Q24: =P24*'Расходы и доставка'!$B$13 | R24: =IFERROR(Q24/L24,0) | S24: 80000 | T24: =L24*S24 | U24: =S24+R24 | V24: =IFERROR(R24/S24,"") | X24: Склад 3
A25: 21 | B25: 3. Остальная бронза и латунь | C25: Ярус 2, рядом на полу | D25: клапан фланцевый | E25: Ду150 | F25: Клапан фланцевый угловой Ду150 Ру10 | G25: 521-01.207 | I25: Комплект | J25: бронза/латунь | K25: 1 | L25: 1 | M25: 75 | N25: =L25*M25 | O25: 0.1 | P25: =IFERROR(IF('Расходы и доставка'!$B$15="по весу",N25/'Расходы и доставка'!$B$19,IF('Расходы и доставка'!$B$15="по объему",O25/'Расходы и доставка'!$B$20,IF('Расходы и доставка'!$B$15="поровну на штуку",L25/'Расходы и доставка'!$B$21,T25/'Расходы и доставка'!$B$22))),0) | Q25: =P25*'Расходы и доставка'!$B$13 | R25: =IFERROR(Q25/L25,0) | S25: 80000 | T25: =L25*S25 | U25: =S25+R25 | V25: =IFERROR(R25/S25,"") | X25: Склад 3
A26: 22 | B26: 3. Остальная бронза и латунь | C26: Ярус 3, ящики | D26: клинкет (задвижка) | E26: Ду80 | F26: Задвижка клинкетная Ду 80 БРОНЗА | I26: Комплект | J26: бронза/латунь | K26: 44 | L26: 44 | M26: 28 | N26: =L26*M26 | O26: 1.32 | P26: =IFERROR(IF('Расходы и доставка'!$B$15="по весу",N26/'Расходы и доставка'!$B$19,IF('Расходы и доставка'!$B$15="по объему",O26/'Расходы и доставка'!$B$20,IF('Расходы и доставка'!$B$15="поровну на штуку",L26/'Расходы и доставка'!$B$21,T26/'Расходы и доставка'!$B$22))),0) | Q26: =P26*'Расходы и доставка'!$B$13 | R26: =IFERROR(Q26/L26,0) | S26: 24000 | T26: =L26*S26 | U26: =S26+R26 | V26: =IFERROR(R26/S26,"") | X26: Склад 1А/1Б
A27: 23 | B27: 3. Остальная бронза и латунь | C27: Ярус 3, ящики | D27: клинкет (задвижка) | E27: Ду100 | F27: Задвижка клинкетная Ду100 | I27: Комплект | J27: бронза/латунь | K27: 6 | L27: 6 | M27: 45 | N27: =L27*M27 | O27: 0.27 | P27: =IFERROR(IF('Расходы и доставка'!$B$15="по весу",N27/'Расходы и доставка'!$B$19,IF('Расходы и доставка'!$B$15="по объему",O27/'Расходы и доставка'!$B$20,IF('Расходы и доставка'!$B$15="поровну на штуку",L27/'Расходы и доставка'!$B$21,T27/'Расходы и доставка'!$B$22))),0) | Q27: =P27*'Расходы и доставка'!$B$13 | R27: =IFERROR(Q27/L27,0) | S27: 38000 | T27: =L27*S27 | U27: =S27+R27 | V27: =IFERROR(R27/S27,"") | X27: Склад 3
A28: 24 | B28: 3. Остальная бронза и латунь | C28: Ярус 3, ящики | D28: клинкет (задвижка) | E28: Ду100 | F28: Задвижка клинкетная Ду100 | I28: Комплект | J28: бронза/латунь | K28: 43 | L28: 43 | M28: 45 | N28: =L28*M28 | O28: 1.935 | P28: =IFERROR(IF('Расходы и доставка'!$B$15="по весу",N28/'Расходы и доставка'!$B$19,IF('Расходы и доставка'!$B$15="по объему",O28/'Расходы и доставка'!$B$20,IF('Расходы и доставка'!$B$15="поровну на штуку",L28/'Расходы и доставка'!$B$21,T28/'Расходы и доставка'!$B$22))),0) | Q28: =P28*'Расходы и доставка'!$B$13 | R28: =IFERROR(Q28/L28,0) | S28: 38000 | T28: =L28*S28 | U28: =S28+R28 | V28: =IFERROR(R28/S28,"") | X28: Склад 3
A29: 25 | B29: 3. Остальная бронза и латунь | C29: Ярус 3, ящики | D29: клинкет (задвижка) | E29: Ду100 | F29: Задвижка клинкетная Ду 100 БРОНЗА | I29: Комплект | J29: бронза/латунь | K29: 2 | L29: 2 | M29: 45 | N29: =L29*M29 | O29: 0.09 | P29: =IFERROR(IF('Расходы и доставка'!$B$15="по весу",N29/'Расходы и доставка'!$B$19,IF('Расходы и доставка'!$B$15="по объему",O29/'Расходы и доставка'!$B$20,IF('Расходы и доставка'!$B$15="поровну на штуку",L29/'Расходы и доставка'!$B$21,T29/'Расходы и доставка'!$B$22))),0) | Q29: =P29*'Расходы и доставка'!$B$13 | R29: =IFERROR(Q29/L29,0) | S29: 35000 | T29: =L29*S29 | U29: =S29+R29 | V29: =IFERROR(R29/S29,"") | X29: Склад 1А/1Б
A30: 26 | B30: 4. Прочее, по цене за килограмм | C30: Ярус 2, рядом на полу | D30: клапан без описания — уточнить | E30: Ду125 | F30: Клапан проходной ДУ 125 корпус | I30: Комплект | K30: 1 | L30: 1 | M30: 5 | N30: =L30*M30 | O30: 0.07 | P30: =IFERROR(IF('Расходы и доставка'!$B$15="по весу",N30/'Расходы и доставка'!$B$19,IF('Расходы и доставка'!$B$15="по объему",O30/'Расходы и доставка'!$B$20,IF('Расходы и доставка'!$B$15="поровну на штуку",L30/'Расходы и доставка'!$B$21,T30/'Расходы и доставка'!$B$22))),0) | Q30: =P30*'Расходы и доставка'!$B$13 | R30: =IFERROR(Q30/L30,0) | S30: 37000 | T30: =L30*S30 | U30: =S30+R30 | V30: =IFERROR(R30/S30,"") | X30: Склад 1А/1Б
A31: 27 | B31: 4. Прочее, по цене за килограмм | C31: Ярус 4, верх | D31: фильтр забортной воды | E31: Ду50 | F31: Фильтр забортной воды Ду 50 | I31: Комплект | K31: 1 | L31: 1 | M31: 15 | N31: =L31*M31 | O31: 0.012 | P31: =IFERROR(IF('Расходы и доставка'!$B$15="по весу",N31/'Расходы и доставка'!$B$19,IF('Расходы и доставка'!$B$15="по объему",O31/'Расходы и доставка'!$B$20,IF('Расходы и доставка'!$B$15="поровну на штуку",L31/'Расходы и доставка'!$B$21,T31/'Расходы и доставка'!$B$22))),0) | Q31: =P31*'Расходы и доставка'!$B$13 | R31: =IFERROR(Q31/L31,0) | S31: 60000 | T31: =L31*S31 | U31: =S31+R31 | V31: =IFERROR(R31/S31,"") | X31: Фойе
A32: 28 | B32: 4. Прочее, по цене за килограмм | C32: Ярус 4, верх | D32: фильтр забортной воды | E32: Ду100 | F32: Фильтр фланц.прох. забортной воды Ду100 Ру4 | G32: 427-03-109-2 | I32: Комплект | K32: 3 | L32: 3 | M32: 40 | N32: =L32*M32 | O32: 0.135 | P32: =IFERROR(IF('Расходы и доставка'!$B$15="по весу",N32/'Расходы и доставка'!$B$19,IF('Расходы и доставка'!$B$15="по объему",O32/'Расходы и доставка'!$B$20,IF('Расходы и доставка'!$B$15="поровну на штуку",L32/'Расходы и доставка'!$B$21,T32/'Расходы и доставка'!$B$22))),0) | Q32: =P32*'Расходы и доставка'!$B$13 | R32: =IFERROR(Q32/L32,0) | S32: 120000 | T32: =L32*S32 | U32: =S32+R32 | V32: =IFERROR(R32/S32,"") | X32: Склад 2
A33: 29 | B33: 4. Прочее, по цене за килограмм | C33: Ярус 4, верх | D33: фильтр забортной воды | E33: Ду100 | F33: Фильтр забортной воды Ду 100 | I33: Комплект | K33: 1 | L33: 1 | M33: 40 | N33: =L33*M33 | O33: 0.045 | P33: =IFERROR(IF('Расходы и доставка'!$B$15="по весу",N33/'Расходы и доставка'!$B$19,IF('Расходы и доставка'!$B$15="по объему",O33/'Расходы и доставка'!$B$20,IF('Расходы и доставка'!$B$15="поровну на штуку",L33/'Расходы и доставка'!$B$21,T33/'Расходы и доставка'!$B$22))),0) | Q33: =P33*'Расходы и доставка'!$B$13 | R33: =IFERROR(Q33/L33,0) | S33: 120000 | T33: =L33*S33 | U33: =S33+R33 | V33: =IFERROR(R33/S33,"") | X33: Фойе
A34: 30 | B34: 4. Прочее, по цене за килограмм | C34: Ярус 3, ящики | D34: клинкет (задвижка) | E34: Ду50 | F34: Задвижка клинкетная Ду 50, без клиньев | I34: Не комплект | K34: 1 | L34: 1 | M34: 12 | N34: =L34*M34 | O34: 0.012 | P34: =IFERROR(IF('Расходы и доставка'!$B$15="по весу",N34/'Расходы и доставка'!$B$19,IF('Расходы и доставка'!$B$15="по объему",O34/'Расходы и доставка'!$B$20,IF('Расходы и доставка'!$B$15="поровну на штуку",L34/'Расходы и доставка'!$B$21,T34/'Расходы и доставка'!$B$22))),0) | Q34: =P34*'Расходы и доставка'!$B$13 | R34: =IFERROR(Q34/L34,0) | S34: 25000 | T34: =L34*S34 | U34: =S34+R34 | V34: =IFERROR(R34/S34,"") | X34: Склад 1А/1Б
A35: 31 | B35: 4. Прочее, по цене за килограмм | C35: Ярус 3, ящики | D35: захлопка | E35: Ду50 | F35: Захлопка фланцевая вертикальная Ду50Ру63 | G35: 529-35.1400-01 | I35: Комплект | K35: 1 | L35: 1 | M35: 12 | N35: =L35*M35 | O35: 0.012 | P35: =IFERROR(IF('Расходы и доставка'!$B$15="по весу",N35/'Расходы и доставка'!$B$19,IF('Расходы и доставка'!$B$15="по объему",O35/'Расходы и доставка'!$B$20,IF('Расходы и доставка'!$B$15="поровну на штуку",L35/'Расходы и доставка'!$B$21,T35/'Расходы и доставка'!$B$22))),0) | Q35: =P35*'Расходы и доставка'!$B$13 | R35: =IFERROR(Q35/L35,0) | S35: 25000 | T35: =L35*S35 | U35: =S35+R35 | V35: =IFERROR(R35/S35,"") | X35: Склад 2
A36: 32 | B36: 4. Прочее, по цене за килограмм | C36: Ярус 3, ящики | D36: захлопка | E36: Ду50 | F36: Захлопка фланцевая горизонтальная Ду50 | G36: 529-03.011 | I36: Комплект | K36: 1 | L36: 1 | M36: 12 | N36: =L36*M36 | O36: 0.012 | P36: =IFERROR(IF('Расходы и доставка'!$B$15="по весу",N36/'Расходы и доставка'!$B$19,IF('Расходы и доставка'!$B$15="по объему",O36/'Расходы и доставка'!$B$20,IF('Расходы и доставка'!$B$15="поровну на штуку",L36/'Расходы и доставка'!$B$21,T36/'Расходы и доставка'!$B$22))),0) | Q36: =P36*'Расходы и доставка'!$B$13 | R36: =IFERROR(Q36/L36,0) | S36: 25000 | T36: =L36*S36 | U36: =S36+R36 | V36: =IFERROR(R36/S36,"") | X36: Склад 2
A37: 33 | B37: 4. Прочее, по цене за килограмм | C37: Ярус 4, верх | D37: фильтр забортной воды | E37: Ду200 | F37: Фильтр забортной воды Ду200 Большой | I37: Комплект | K37: 8 | L37: 8 | M37: 120 | N37: =L37*M37 | O37: 1.28 | P37: =IFERROR(IF('Расходы и доставка'!$B$15="по весу",N37/'Расходы и доставка'!$B$19,IF('Расходы и доставка'!$B$15="по объему",O37/'Расходы и доставка'!$B$20,IF('Расходы и доставка'!$B$15="поровну на штуку",L37/'Расходы и доставка'!$B$21,T37/'Расходы и доставка'!$B$22))),0) | Q37: =P37*'Расходы и доставка'!$B$13 | R37: =IFERROR(Q37/L37,0) | S37: 250000 | T37: =L37*S37 | U37: =S37+R37 | V37: =IFERROR(R37/S37,"") | X37: Фойе
A38: 34 | B38: 4. Прочее, по цене за килограмм | C38: Ярус 3, ящики | D38: клапан без описания — уточнить | F38: Судовая запорная арматура | I38: Комплект | K38: 2 | L38: 2 | M38: 5 | N38: =L38*M38 | O38: 0.02 | P38: =IFERROR(IF('Расходы и доставка'!$B$15="по весу",N38/'Расходы и доставка'!$B$19,IF('Расходы и доставка'!$B$15="по объему",O38/'Расходы и доставка'!$B$20,IF('Расходы и доставка'!$B$15="поровну на штуку",L38/'Расходы и доставка'!$B$21,T38/'Расходы и доставка'!$B$22))),0) | Q38: =P38*'Расходы и доставка'!$B$13 | R38: =IFERROR(Q38/L38,0) | S38: 10000 | T38: =L38*S38 | U38: =S38+R38 | V38: =IFERROR(R38/S38,"") | X38: Менеджерская
A39: 35 | B39: 4. Прочее, по цене за килограмм | C39: Ярус 4, верх | D39: фильтр забортной воды | E39: Ду150 | F39: Фильтр заборной воды ДУ 150 | I39: Комплект | K39: 5 | L39: 5 | M39: 75 | N39: =L39*M39 | O39: 0.5 | P39: =IFERROR(IF('Расходы и доставка'!$B$15="по весу",N39/'Расходы и доставка'!$B$19,IF('Расходы и доставка'!$B$15="по объему",O39/'Расходы и доставка'!$B$20,IF('Расходы и доставка'!$B$15="поровну на штуку",L39/'Расходы и доставка'!$B$21,T39/'Расходы и доставка'!$B$22))),0) | Q39: =P39*'Расходы и доставка'!$B$13 | R39: =IFERROR(Q39/L39,0) | S39: 150000 | T39: =L39*S39 | U39: =S39+R39 | V39: =IFERROR(R39/S39,"") | X39: Фойе
A40: 36 | B40: 4. Прочее, по цене за килограмм | C40: Ярус 3, ящики | D40: клапан фланцевый | E40: Ду50 | F40: Клапан фланцевый проходной невозвратный Ду 50 РУ 25 (522-01.164) | I40: Комплект | K40: 1 | L40: 1 | M40: 14 | N40: =L40*M40 | O40: 0.012 | P40: =IFERROR(IF('Расходы и доставка'!$B$15="по весу",N40/'Расходы и доставка'!$B$19,IF('Расходы и доставка'!$B$15="по объему",O40/'Расходы и доставка'!$B$20,IF('Расходы и доставка'!$B$15="поровну на штуку",L40/'Расходы и доставка'!$B$21,T40/'Расходы и доставка'!$B$22))),0) | Q40: =P40*'Расходы и доставка'!$B$13 | R40: =IFERROR(Q40/L40,0) | S40: 25000 | T40: =L40*S40 | U40: =S40+R40 | V40: =IFERROR(R40/S40,"") | X40: Склад 1А/1Б
A41: 37 | B41: 4. Прочее, по цене за килограмм | C41: Ярус 3, ящики | D41: клапан пожарный | E41: Ду50 | F41: Клапан Пожарный фланцевый угловой Ду50 Ру16 | G41: 595-03.011 | I41: Комплект | K41: 3 | L41: 3 | M41: 14 | N41: =L41*M41 | O41: 0.036 | P41: =IFERROR(IF('Расходы и доставка'!$B$15="по весу",N41/'Расходы и доставка'!$B$19,IF('Расходы и доставка'!$B$15="по объему",O41/'Расходы и доставка'!$B$20,IF('Расходы и доставка'!$B$15="поровну на штуку",L41/'Расходы и доставка'!$B$21,T41/'Расходы и доставка'!$B$22))),0) | Q41: =P41*'Расходы и доставка'!$B$13 | R41: =IFERROR(Q41/L41,0) | S41: 25000 | T41: =L41*S41 | U41: =S41+R41 | V41: =IFERROR(R41/S41,"") | X41: Менеджерская
...

Sheet Итоги по состоянию
A1: Новое и б/у: сколько чего уехало
A2: Считается по колонке «Состояние» листа «Отгрузка». Пока она не заполнена, все попадет в строку «не указано».
A4: Состояние | B4: Позиций | C4: Штук | D4: Вес, кг | E4: Стоимость, руб | F4: Доставка, руб | G4: Всего с доставкой, руб
A5: Новое | B5: =COUNTIF('Отгрузка'!H$5:H$149,"Новое") | C5: =SUMIF('Отгрузка'!H$5:H$149,"Новое",'Отгрузка'!L$5:L$149) | D5: =SUMIF('Отгрузка'!H$5:H$149,"Новое",'Отгрузка'!N$5:N$149) | E5: =SUMIF('Отгрузка'!H$5:H$149,"Новое",'Отгрузка'!T$5:T$149) | F5: =SUMIF('Отгрузка'!H$5:H$149,"Новое",'Отгрузка'!Q$5:Q$149) | G5: =E5+F5
A6: Б/у | B6: =COUNTIF('Отгрузка'!H$5:H$149,"Б/у") | C6: =SUMIF('Отгрузка'!H$5:H$149,"Б/у",'Отгрузка'!L$5:L$149) | D6: =SUMIF('Отгрузка'!H$5:H$149,"Б/у",'Отгрузка'!N$5:N$149) | E6: =SUMIF('Отгрузка'!H$5:H$149,"Б/у",'Отгрузка'!T$5:T$149) | F6: =SUMIF('Отгрузка'!H$5:H$149,"Б/у",'Отгрузка'!Q$5:Q$149) | G6: =E6+F6
A7: Восстановленное | B7: =COUNTIF('Отгрузка'!H$5:H$149,"Восстановленное") | C7: =SUMIF('Отгрузка'!H$5:H$149,"Восстановленное",'Отгрузка'!L$5:L$149) | D7: =SUMIF('Отгрузка'!H$5:H$149,"Восстановленное",'Отгрузка'!N$5:N$149) | E7: =SUMIF('Отгрузка'!H$5:H$149,"Восстановленное",'Отгрузка'!T$5:T$149) | F7: =SUMIF('Отгрузка'!H$5:H$149,"Восстановленное",'Отгрузка'!Q$5:Q$149) | G7: =E7+F7
A8: не указано | B8: =COUNTBLANK('Отгрузка'!H$5:H$149) | C8: =SUMIF('Отгрузка'!H$5:H$149,"",'Отгрузка'!L$5:L$149) | D8: =SUMIF('Отгрузка'!H$5:H$149,"",'Отгрузка'!N$5:N$149) | E8: =SUMIF('Отгрузка'!H$5:H$149,"",'Отгрузка'!T$5:T$149) | F8: =SUMIF('Отгрузка'!H$5:H$149,"",'Отгрузка'!Q$5:Q$149) | G8: =E8+F8
A9: ИТОГО | B9: =SUM(B5:B8) | C9: =SUM(C5:C8) | D9: =SUM(D5:D8) | E9: =SUM(E5:E8) | F9: =SUM(F5:F8) | G9: =SUM(G5:G8)
A11: Проверка
A12: Разнесено доставки, руб | B12: =SUM('Отгрузка'!Q$5:Q$149)
A13: Введено расходов, руб | B13: ='Расходы и доставка'!$B$13
A14: Расхождение, руб | B14: =SUM('Отгрузка'!Q$5:Q$149)-'Расходы и доставка'!$B$13
A15: Расхождение должно быть нулевым. Если не ноль — в отгрузке есть строка без веса или без цены, и доля по ней не посчиталась.
