Workbook

Sheet Расходы на доставку
A1: Во что обойдется доставка двух контейнеров
A2: Желтое вводим сами: ставок на момент сборки файла нет. Все остальное считается. Цена килограмма отсюда идет в себестоимость каждой позиции.
A4: Расход | B4: Контейнер 1 | C4: Контейнер 2 | D4: Итого
A5: Аренда или покупка контейнера | D5: =B5+C5
A6: Фрахт Владивосток — Петербург | D6: =B6+C6
A7: Автодоставка до терминала во Владивостоке | D7: =B7+C7
A8: Погрузка, кран, такелаж | D8: =B8+C8
A9: Тара: поддоны, доска, брус, ящики | D9: =B9+C9
A10: Упаковочные материалы | D10: =B10+C10
A11: Страхование груза | D11: =B11+C11
A12: Выгрузка и автодоставка на склад в Питере | D12: =B12+C12
A13: Прочее | D13: =B13+C13
A14: ИТОГО расходов | B14: =SUM(B5:B13) | C14: =SUM(C5:C13) | D14: =SUM(D5:D13)
A16: Что везем
A17: Вес груза, кг | B17: 20000 | C17: 12553 | D17: =B17+C17
A18: Доставка за килограмм, руб | B18: =IFERROR(B14/B17,0) | C18: =IFERROR(C14/C17,0) | D18: =IFERROR(D14/D17,0)
A20: — Для сравнения: транспортная компания по распискам от 24.09.2026 обошлась в 81 руб за килограмм. Контейнер должен выйти в разы дешевле, иначе он не нужен.
A21: — Загрузка по весу: Контейнер 1 20.0 т из 20, Контейнер 2 12.6 т из 20.
A22: — Хранение в Питере в эти расходы не входит. Если арматура пролежит на складе год-два, хранение может обойтись дороже самой доставки — ставку надо узнать заранее.

Sheet Цена на складе в Питере
A1: Приемка и цена продажи на складе в Петербурге
A2: Принимаем груз по колонке «Принято», расхождение считается само. Себестоимость в Питере — цена склада плюс доставка по весу. От нее ставим цену продажи.
A4: № | B4: Контейнер | C4: Тип | D4: Диаметр | E4: Наименование | F4: Материал | G4: Состояние | H4: Отправлено, шт | I4: Принято в Питере, шт | J4: Расхождение | K4: Вес ед., кг | L4: Доставка на ед., руб | M4: Цена склада, руб | N4: Себестоимость в Питере, руб | O4: Доставка в цене | P4: Цена продажи в Питере, руб | Q4: Наценка | R4: № места | S4: Примечание
A5: 1 | B5: Контейнер 1 | C5: клинкет (задвижка) | D5: Ду250 | E5: Клинкет Ду 250 | F5: проверить: везем бронзу и латунь | H5: 2 | J5: =IF(I5="","",I5-H5) | K5: 220 | L5: =K5*'Расходы на доставку'!$B$18 | M5: 200000 | N5: =IF(M5="","",M5+L5) | O5: =IFERROR(L5/N5,"") | Q5: =IFERROR(P5/N5-1,"")
A6: 2 | B6: Контейнер 1 | C6: клинкет (задвижка) | D6: Ду250 | E6: Клинкет Ду 250 не комплект | F6: проверить: везем бронзу и латунь | H6: 2 | J6: =IF(I6="","",I6-H6) | K6: 220 | L6: =K6*'Расходы на доставку'!$B$18 | M6: 200000 | N6: =IF(M6="","",M6+L6) | O6: =IFERROR(L6/N6,"") | Q6: =IFERROR(P6/N6-1,"")
A7: 3 | B7: Контейнер 1 | C7: клинкет (задвижка) | D7: Ду300 | E7: Клинкет Ду 300 | F7: проверить: везем бронзу и латунь | H7: 16 | J7: =IF(I7="","",I7-H7) | K7: 300 | L7: =K7*'Расходы на доставку'!$B$18 | M7: 250000 | N7: =IF(M7="","",M7+L7) | O7: =IFERROR(L7/N7,"") | Q7: =IFERROR(P7/N7-1,"")
A8: 4 | B8: Контейнер 1 | C8: клинкет (задвижка) | D8: Ду350 | E8: Клинкет Ду 350 | F8: проверить: везем бронзу и латунь | H8: 1 | J8: =IF(I8="","",I8-H8) | K8: 400 | L8: =K8*'Расходы на доставку'!$B$18 | M8: 300000 | N8: =IF(M8="","",M8+L8) | O8: =IFERROR(L8/N8,"") | Q8: =IFERROR(P8/N8-1,"")
A9: 5 | B9: Контейнер 1 | C9: клинкет (задвижка) | D9: Ду250 | E9: Задвижка клинкетная Ду 250 | F9: проверить: везем бронзу и латунь | H9: 17 | J9: =IF(I9="","",I9-H9) | K9: 220 | L9: =K9*'Расходы на доставку'!$B$18 | M9: 150000 | N9: =IF(M9="","",M9+L9) | O9: =IFERROR(L9/N9,"") | Q9: =IFERROR(P9/N9-1,"")
A10: 6 | B10: Контейнер 1 | C10: клапан фланцевый | D10: Ду50 | E10: Клапан фланцевый проходной титановые Ду50Ру10 | F10: титан | H10: 5 | J10: =IF(I10="","",I10-H10) | K10: 14 | L10: =K10*'Расходы на доставку'!$B$18 | N10: =IF(M10="","",M10+L10) | O10: =IFERROR(L10/N10,"") | Q10: =IFERROR(P10/N10-1,"")
A11: 7 | B11: Контейнер 1 | C11: клапан фланцевый | D11: Ду100 | E11: Клапан фланцевый проходной титановые Ду100Ру10 | F11: титан | H11: 1 | J11: =IF(I11="","",I11-H11) | K11: 40 | L11: =K11*'Расходы на доставку'!$B$18 | N11: =IF(M11="","",M11+L11) | O11: =IFERROR(L11/N11,"") | Q11: =IFERROR(P11/N11-1,"")
A12: 8 | B12: Контейнер 1 | C12: клапан фланцевый | D12: Ду25 | E12: Клапан фланцевый угловой Ду25 | F12: бронза/латунь | H12: 15 | J12: =IF(I12="","",I12-H12) | K12: 5 | L12: =K12*'Расходы на доставку'!$B$18 | M12: 9600 | N12: =IF(M12="","",M12+L12) | O12: =IFERROR(L12/N12,"") | Q12: =IFERROR(P12/N12-1,"")
A13: 9 | B13: Контейнер 1 | C13: клапан фланцевый | D13: Ду40 | E13: Клапан фланцевый угловой Ду40 Ру25 | F13: бронза/латунь | H13: 1 | J13: =IF(I13="","",I13-H13) | K13: 10 | L13: =K13*'Расходы на доставку'!$B$18 | M13: 18000 | N13: =IF(M13="","",M13+L13) | O13: =IFERROR(L13/N13,"") | Q13: =IFERROR(P13/N13-1,"")
A14: 10 | B14: Контейнер 1 | C14: клапан фланцевый | D14: Ду50 | E14: Клапан фланцевый угловой Ду50 Ру25 | F14: бронза/латунь | H14: 7 | J14: =IF(I14="","",I14-H14) | K14: 14 | L14: =K14*'Расходы на доставку'!$B$18 | M14: 22500 | N14: =IF(M14="","",M14+L14) | O14: =IFERROR(L14/N14,"") | Q14: =IFERROR(P14/N14-1,"")
A15: 11 | B15: Контейнер 1 | C15: клапан фланцевый | D15: Ду40 | E15: Клапан фланцевый угловой Ду40 Ру10 | F15: бронза/латунь | H15: 1 | J15: =IF(I15="","",I15-H15) | K15: 10 | L15: =K15*'Расходы на доставку'!$B$18 | M15: 16000 | N15: =IF(M15="","",M15+L15) | O15: =IFERROR(L15/N15,"") | Q15: =IFERROR(P15/N15-1,"")
A16: 12 | B16: Контейнер 1 | C16: клинкет (задвижка) | D16: Ду65 | E16: Задвижка клинкетная Ду65 | F16: бронза/латунь | H16: 16 | J16: =IF(I16="","",I16-H16) | K16: 18 | L16: =K16*'Расходы на доставку'!$B$18 | M16: 27000 | N16: =IF(M16="","",M16+L16) | O16: =IFERROR(L16/N16,"") | Q16: =IFERROR(P16/N16-1,"")
A17: 13 | B17: Контейнер 1 | C17: клапан фланцевый | D17: Ду65 | E17: Клапан фланцевый угловой Ду65 Ру10 | F17: бронза/латунь | H17: 6 | J17: =IF(I17="","",I17-H17) | K17: 20 | L17: =K17*'Расходы на доставку'!$B$18 | M17: 27000 | N17: =IF(M17="","",M17+L17) | O17: =IFERROR(L17/N17,"") | Q17: =IFERROR(P17/N17-1,"")
A18: 14 | B18: Контейнер 1 | C18: клапан фланцевый | D18: Ду65 | E18: Клапан фланцевый угловой Ду65 Ру10 | F18: бронза/латунь | H18: 3 | J18: =IF(I18="","",I18-H18) | K18: 20 | L18: =K18*'Расходы на доставку'!$B$18 | M18: 27000 | N18: =IF(M18="","",M18+L18) | O18: =IFERROR(L18/N18,"") | Q18: =IFERROR(P18/N18-1,"")
A19: 15 | B19: Контейнер 1 | C19: клапан фланцевый | D19: Ду65 | E19: Клапан фланцевый угловой Ду65 Ру10 | F19: бронза/латунь | H19: 12 | J19: =IF(I19="","",I19-H19) | K19: 20 | L19: =K19*'Расходы на доставку'!$B$18 | M19: 27000 | N19: =IF(M19="","",M19+L19) | O19: =IFERROR(L19/N19,"") | Q19: =IFERROR(P19/N19-1,"")
A20: 16 | B20: Контейнер 1 | C20: клинкет (задвижка) | D20: Ду70 | E20: Задвижка клинкетная фланцевая Ду70 Ру6 | F20: бронза/латунь | H20: 7 | J20: =IF(I20="","",I20-H20) | K20: 22 | L20: =K20*'Расходы на доставку'!$B$18 | M20: 27000 | N20: =IF(M20="","",M20+L20) | O20: =IFERROR(L20/N20,"") | Q20: =IFERROR(P20/N20-1,"")
A21: 17 | B21: Контейнер 1 | C21: клапан фланцевый | D21: Ду80 | E21: Клапан фланцевый угловой Ду80 | F21: бронза/латунь | H21: 7 | J21: =IF(I21="","",I21-H21) | K21: 28 | L21: =K21*'Расходы на доставку'!$B$18 | M21: 34000 | N21: =IF(M21="","",M21+L21) | O21: =IFERROR(L21/N21,"") | Q21: =IFERROR(P21/N21-1,"")
A22: 18 | B22: Контейнер 1 | C22: клинкет (задвижка) | D22: Ду80 | E22: Задвижка клинкетная фланцевая Ду80 Ру6 | F22: бронза/латунь | H22: 18 | J22: =IF(I22="","",I22-H22) | K22: 28 | L22: =K22*'Расходы на доставку'!$B$18 | M22: 32000 | N22: =IF(M22="","",M22+L22) | O22: =IFERROR(L22/N22,"") | Q22: =IFERROR(P22/N22-1,"")
A23: 19 | B23: Контейнер 1 | C23: клинкет (задвижка) | D23: Ду60 | E23: Задвижка клинкетная Ду60 | F23: бронза/латунь | H23: 1 | J23: =IF(I23="","",I23-H23) | K23: 16 | L23: =K23*'Расходы на доставку'!$B$18 | M23: 18000 | N23: =IF(M23="","",M23+L23) | O23: =IFERROR(L23/N23,"") | Q23: =IFERROR(P23/N23-1,"")
... A29: 25 | B29: Контейнер 1 | C29: клинкет (задвижка) | D29: Ду100 | E29: Задвижка клинкетная Ду 100 БРОНЗА | F29: бронза/латунь | H29: 2 | J29: =IF(I29="","",I29-H29) | K29: 45 | L29: =K29*'Расходы на доставку'!$B$18 | M29: 35000 | N29: =IF(M29="","",M29+L29) | O29: =IFERROR(L29/N29,"") | Q29: =IFERROR(P29/N29-1,"")
A30: 26 | B30: Контейнер 1 | C30: клапан штуцерный | D30: Ду10 | E30: Клапан штуцерный угловой Ду10 Ру100 | H30: 1 | J30: =IF(I30="","",I30-H30) | K30: 0.6 | L30: =K30*'Расходы на доставку'!$B$18 | M30: 20200 | N30: =IF(M30="","",M30+L30) | O30: =IFERROR(L30/N30,"") | Q30: =IFERROR(P30/N30-1,"")
A31: 27 | B31: Контейнер 1 | C31: клапан штуцерный | D31: Ду6 | E31: Клапан предохранительный штуцерный угловой Ду6,5-9 | H31: 1 | J31: =IF(I31="","",I31-H31) | K31: 0.4 | L31: =K31*'Расходы на доставку'!$B$18 | M31: 9000 | N31: =IF(M31="","",M31+L31) | O31: =IFERROR(L31/N31,"") | Q31: =IFERROR(P31/N31-1,"")
A32: 28 | B32: Контейнер 1 | C32: клапан штуцерный | D32: Ду3 | E32: Клапан для манометра штущерный Ду3Ру400 новый | H32: 2 | J32: =IF(I32="","",I32-H32) | K32: 0.3 | L32: =K32*'Расходы на доставку'!$B$18 | M32: 6000 | N32: =IF(M32="","",M32+L32) | O32: =IFERROR(L32/N32,"") | Q32: =IFERROR(P32/N32-1,"")
A33: 29 | B33: Контейнер 1 | C33: клапан штуцерный | D33: Ду10 | E33: Клапан штуцерный проходной Ду 10 Ру40 (СУНДУК) | H33: 798 | J33: =IF(I33="","",I33-H33) | K33: 0.6 | L33: =K33*'Расходы на доставку'!$B$18 | M33: 9000 | N33: =IF(M33="","",M33+L33) | O33: =IFERROR(L33/N33,"") | Q33: =IFERROR(P33/N33-1,"")
A34: 30 | B34: Контейнер 1 | C34: клапан штуцерный | D34: Ду6 | E34: Клапан для манометра штущерный сальниковый Ду6Ру100 новый | H34: 95 | J34: =IF(I34="","",I34-H34) | K34: 0.4 | L34: =K34*'Расходы на доставку'!$B$18 | M34: 4500 | N34: =IF(M34="","",M34+L34) | O34: =IFERROR(L34/N34,"") | Q34: =IFERROR(P34/N34-1,"")
A35: 31 | B35: Контейнер 1 | C35: клапан штуцерный | D35: Ду6 | E35: Клапан для манометра штущерный сальниковый Ду6Ру100 б/у | H35: 1 | J35: =IF(I35="","",I35-H35) | K35: 0.4 | L35: =K35*'Расходы на доставку'!$B$18 | M35: 4500 | N35: =IF(M35="","",M35+L35) | O35: =IFERROR(L35/N35,"") | Q35: =IFERROR(P35/N35-1,"")
A36: 32 | B36: Контейнер 1 | C36: клапан штуцерный | D36: Ду6 | E36: Клапан для манометра штущерный сальниковый Ду6Ру100 б/у | H36: 1 | J36: =IF(I36="","",I36-H36) | K36: 0.4 | L36: =K36*'Расходы на доставку'!$B$18 | M36: 4500 | N36: =IF(M36="","",M36+L36) | O36: =IFERROR(L36/N36,"") | Q36: =IFERROR(P36/N36-1,"")
A37: 33 | B37: Контейнер 1 | C37: клапан штуцерный | D37: Ду6 | E37: Клапан предохранительный штуцерный сигнальный Ду6 Ру100-230 | H37: 1 | J37: =IF(I37="","",I37-H37) | K37: 0.4 | L37: =K37*'Расходы на доставку'!$B$18 | M37: 4500 | N37: =IF(M37="","",M37+L37) | O37: =IFERROR(L37/N37,"") | Q37: =IFERROR(P37/N37-1,"")
A38: 34 | B38: Контейнер 1 | C38: клапан штуцерный | D38: Ду6 | E38: Клапан предохранительный штуцерный сигнальный Ду6Ру100-250 | H38: 2 | J38: =IF(I38="","",I38-H38) | K38: 0.4 | L38: =K38*'Расходы на доставку'!$B$18 | M38: 4500 | N38: =IF(M38="","",M38+L38) | O38: =IFERROR(L38/N38,"") | Q38: =IFERROR(P38/N38-1,"")
A39: 35 | B39: Контейнер 1 | C39: клапан штуцерный | D39: Ду10 | E39: Клапан штуцерный проходной Ду 10 Ру400 | H39: 1 | J39: =IF(I39="","",I39-H39) | K39: 0.6 | L39: =K39*'Расходы на доставку'!$B$18 | M39: 6000 | N39: =IF(M39="","",M39+L39) | O39: =IFERROR(L39/N39,"") | Q39: =IFERROR(P39/N39-1,"")
A40: 36 | B40: Контейнер 1 | C40: клапан штуцерный | D40: Ду10 | E40: Клапан штуцерный проходной Ду 10 Ру400 | H40: 2 | J40: =IF(I40="","",I40-H40) | K40: 0.6 | L40: =K40*'Расходы на доставку'!$B$18 | M40: 6000 | N40: =IF(M40="","",M40+L40) | O40: =IFERROR(L40/N40,"") | Q40: =IFERROR(P40/N40-1,"")
A41: 37 | B41: Контейнер 1 | C41: клапан штуцерный | D41: Ду10 | E41: Клапан редукционный штуцерный угловой Ду10Ру200…30 с манометром | H41: 1 | J41: =IF(I41="","",I41-H41) | K41: 0.6 | L41: =K41*'Расходы на доставку'!$B$18 | M41: 6000 | N41: =IF(M41="","",M41+L41) | O41: =IFERROR(L41/N41,"") | Q41: =IFERROR(P41/N41-1,"")
... A126: 122 | B126: Контейнер 1 | C126: клапан штуцерный | D126: Ду10 | E126: Клапан штуцерный проходной Ду 10 | H126: 4 | J126: =IF(I126="","",I126-H126) | K126: 0.6 | L126: =K126*'Расходы на доставку'!$B$18 | M126: 2000 | N126: =IF(M126="","",M126+L126) | O126: =IFERROR(L126/N126,"") | Q126: =IFERROR(P126/N126-1,"")
A127: 123 | B127: Контейнер 1 | C127: клапан штуцерный | D127: Ду10 | E127: Клапан штуцерный проходной Ду 10 Ру25 СТАЛЬ | F127: сталь | H127: 1 | J127: =IF(I127="","",I127-H127) | K127: 0.6 | L127: =K127*'Расходы на доставку'!$B$18 | M127: 2000 | N127: =IF(M127="","",M127+L127) | O127: =IFERROR(L127/N127,"") | Q127: =IFERROR(P127/N127-1,"")
A128: 124 | B128: Контейнер 1 | C128: клапан штуцерный | D128: Ду10 | E128: Клапан штуцерный проходной Ду 10 Ру63 СТАЛЬ | F128: сталь | H128: 1 | J128: =IF(I128="","",I128-H128) | K128: 0.6 | L128: =K128*'Расходы на доставку'!$B$18 | M128: 2000 | N128: =IF(M128="","",M128+L128) | O128: =IFERROR(L128/N128,"") | Q128: =IFERROR(P128/N128-1,"")
A129: 125 | B129: Контейнер 1 | C129: клапан штуцерный | D129: Ду20 | E129: Клапан невозв-запор.цапковый угловой под дюрит Ду20Ру6 | H129: 2 | J129: =IF(I129="","",I129-H129) | K129: 1.5 | L129: =K129*'Расходы на доставку'!$B$18 | M129: 4800 | N129: =IF(M129="","",M129+L129) | O129: =IFERROR(L129/N129,"") | Q129: =IFERROR(P129/N129-1,"")
A130: 126 | B130: Контейнер 1 | C130: фильтр забортной воды | D130: Ду100 | E130: Фильтр фланц.прох. забортной воды Ду100 Ру4 | H130: 3 | J130: =IF(I130="","",I130-H130) | K130: 40 | L130: =K130*'Расходы на доставку'!$B$18 | M130: 120000 | N130: =IF(M130="","",M130+L130) | O130: =IFERROR(L130/N130,"") | Q130: =IFERROR(P130/N130-1,"")
...

Sheet Итоги по складу
A1: Что лежит на складе в Питере и сколько это стоит
A2: Считается по листу цены. Пока приемка не заполнена, часть строк будет пустой.
A4: По контейнерам
A5: Контейнер | B5: Позиций | C5: Отправлено, шт | D5: Принято, шт | E5: Цена склада, руб | F5: Доставка, руб | G5: Себестоимость в Питере, руб
A6: Контейнер 1 | B6: =COUNTIF('Цена на складе в Питере'!$B$5:$B$274,"Контейнер 1") | C6: =SUMIF('Цена на складе в Питере'!$B$5:$B$274,"Контейнер 1",'Цена на складе в Питере'!$H$5:$H$274) | D6: =SUMIF('Цена на складе в Питере'!$B$5:$B$274,"Контейнер 1",'Цена на складе в Питере'!$I$5:$I$274) | E6: =SUMPRODUCT(('Цена на складе в Питере'!$B$5:$B$274="Контейнер 1")*IFERROR('Цена на складе в Питере'!$H$5:$H$274*'Цена на складе в Питере'!$M$5:$M$274,0)) | F6: =SUMPRODUCT(('Цена на складе в Питере'!$B$5:$B$274="Контейнер 1")*IFERROR('Цена на складе в Питере'!$H$5:$H$274*'Цена на складе в Питере'!$L$5:$L$274,0)) | G6: =E6+F6
A7: Контейнер 2 | B7: =COUNTIF('Цена на складе в Питере'!$B$5:$B$274,"Контейнер 2") | C7: =SUMIF('Цена на складе в Питере'!$B$5:$B$274,"Контейнер 2",'Цена на складе в Питере'!$H$5:$H$274) | D7: =SUMIF('Цена на складе в Питере'!$B$5:$B$274,"Контейнер 2",'Цена на складе в Питере'!$I$5:$I$274) | E7: =SUMPRODUCT(('Цена на складе в Питере'!$B$5:$B$274="Контейнер 2")*IFERROR('Цена на складе в Питере'!$H$5:$H$274*'Цена на складе в Питере'!$M$5:$M$274,0)) | F7: =SUMPRODUCT(('Цена на складе в Питере'!$B$5:$B$274="Контейнер 2")*IFERROR('Цена на складе в Питере'!$H$5:$H$274*'Цена на складе в Питере'!$L$5:$L$274,0)) | G7: =E7+F7
A8: ИТОГО | B8: =SUM(B6:B7) | C8: =SUM(C6:C7) | D8: =SUM(D6:D7) | E8: =SUM(E6:E7) | F8: =SUM(F6:F7) | G8: =SUM(G6:G7)
A10: Приемка
A11: Строк принято | B11: =COUNT('Цена на складе в Питере'!$I$5:$I$274)
A12: Строк осталось принять | B12: =COUNTA('Цена на складе в Питере'!$E$5:$E$274)-COUNT('Цена на складе в Питере'!$I$5:$I$274)
A13: Расхождение всего, шт | B13: =SUM('Цена на складе в Питере'!$J$5:$J$274)
A14: Строк с расхождением | B14: =COUNTIF('Цена на складе в Питере'!$J$5:$J$274,"<>0")-COUNTBLANK('Цена на складе в Питере'!$J$5:$J$274)

Sheet Как работать с файлом
A1: Порядок работы
A3: № | B3: Правило | C3: Почему так
A4: 1 | B4: Сначала расходы, потом цены | C4: Пока на листе расходов нули, доставка на единицу будет нулевой, и себестоимость в Питере совпадет с ценой склада. Ставить цену продажи от такой цифры нельзя.
A5: 2 | B5: Принимаем по местам, а не по памяти | C5: Номер места в этой таблице должен совпадать с биркой на ящике и строкой упаковочного листа. Расхождение фиксируем в день выгрузки, иначе повторим владивостокскую историю с недостоверными остатками.
A6: 3 | B6: Состояние переносим из отгрузки | C6: Новое и б/у на питерском складе продаются по разной цене. Если состояние не проставили при погрузке, на приемке это уже спорно.
A7: 4 | B7: Цена продажи считается от себестоимости в Питере | C7: Это цена склада плюс доставка. На тяжелой арматуре доставка заметна, на мелочи почти нет — поэтому наценку ставим по строке, а не одним процентом на весь склад.
A8: 5 | B8: Хранение считаем отдельно | C8: Доставка — разовый расход, хранение идет каждый месяц. Если арматура лежит год-два, хранение способно перекрыть доставку. Ставку за квадратный метр или за паллетоместо надо знать до того, как контейнеры выехали.
A9: 6 | B9: Позиции без цены не продаем вслепую | C9: В складских файлах часть позиций идет без цены. Пока цена не проставлена, себестоимость в Питере по ним не считается.
